{
  "timestamp": "2025-07-21T17:51:50.959581",
  "mcp_url": "http://192.168.0.152:8007",
  "test_suites": {
    "connectivity": {
      "results": [
        [
          "tool_discovery",
          {
            "success": true,
            "tools": [
              {
                "name": "create_gaea2_project",
                "description": "Create a Gaea2 terrain project with automatic validation",
                "parameters": {
                  "project_name": "Name of the project",
                  "workflow": "List of nodes and connections",
                  "auto_validate": "Automatically validate and fix (default: true)"
                }
              },
              {
                "name": "run_gaea2_project",
                "description": "Run a Gaea2 project using CLI automation",
                "parameters": {
                  "project_path": "Path to the .terrain file",
                  "output_dir": "Output directory (optional)",
                  "variables": "Variables to pass to Gaea2 (optional)",
                  "verbose": "Enable verbose logging (default: true)",
                  "ignore_cache": "Ignore baked cache (default: false)",
                  "seed": "Mutation seed (optional)"
                }
              },
              {
                "name": "validate_and_fix_workflow",
                "description": "Comprehensive workflow validation and fixing",
                "parameters": {
                  "workflow": "Workflow or path to workflow file",
                  "fix_errors": "Automatically fix errors (default: true)",
                  "validate_connections": "Validate node connections (default: true)",
                  "validate_properties": "Validate node properties (default: true)",
                  "add_missing_nodes": "Add missing essential nodes (default: true)",
                  "optimize_workflow": "Suggest optimizations (default: false)"
                }
              },
              {
                "name": "analyze_execution_history",
                "description": "Analyze execution history to learn from runs",
                "parameters": {}
              },
              {
                "name": "create_gaea2_from_template",
                "description": "Create project from template",
                "parameters": {
                  "template_name": "Template name",
                  "project_name": "Project name",
                  "customizations": "Optional customizations"
                }
              },
              {
                "name": "analyze_workflow_patterns",
                "description": "Analyze workflow patterns",
                "parameters": {
                  "workflow_or_directory": "Workflow or directory path",
                  "include_suggestions": "Include suggestions (default: true)"
                }
              },
              {
                "name": "suggest_gaea2_nodes",
                "description": "Get intelligent node suggestions",
                "parameters": {
                  "current_nodes": "List of current nodes",
                  "context": "Optional context",
                  "limit": "Max suggestions (default: 5)"
                }
              },
              {
                "name": "repair_gaea2_project",
                "description": "Repair damaged Gaea2 project",
                "parameters": {
                  "project_path": "Path to project file",
                  "backup": "Create backup (default: true)",
                  "aggressive": "Aggressive repair (default: false)"
                }
              },
              {
                "name": "optimize_gaea2_properties",
                "description": "Optimize node properties",
                "parameters": {
                  "workflow": "Workflow to optimize",
                  "optimization_mode": "Mode: 'performance', 'quality', or 'balanced'"
                }
              }
            ]
          }
        ],
        [
          "basic_operation",
          {
            "success": true,
            "result": {
              "success": true,
              "project_name": "test_connectivity_20250721_175151",
              "node_count": 5,
              "connection_count": 4,
              "saved_path": "C:\\Gaea2\\MCP_Projects\\test_connectivity_20250721_175151.terrain",
              "project_path": "C:\\Gaea2\\MCP_Projects\\test_connectivity_20250721_175151.terrain",
              "project_structure": {
                "$id": "1",
                "Assets": {
                  "$id": "2",
                  "$values": [
                    {
                      "$id": "3",
                      "Terrain": {
                        "$id": "4",
                        "Id": "8c3f61a5-845d-4cab-ae57-38777add8920",
                        "Metadata": {
                          "$id": "5",
                          "Name": "test_connectivity_20250721_175151",
                          "Description": "Created by Gaea2 MCP Server",
                          "Version": "",
                          "DateCreated": "2025-07-21 17:51:52Z",
                          "DateLastBuilt": "2025-07-21 17:51:52Z",
                          "DateLastSaved": "2025-07-21 17:51:52Z"
                        },
                        "Nodes": {
                          "$id": "6",
                          "100": {
                            "$id": "7",
                            "$type": "QuadSpinner.Gaea.Nodes.Mountain, Gaea.Nodes",
                            "Scale": 1.0,
                            "Height": 0.7,
                            "Style": "Alpine",
                            "Bulk": "Medium",
                            "ReduceDetails": false,
                            "Seed": 0,
                            "X": 0.0,
                            "Y": 0.0,
                            "Id": 100,
                            "Name": "BaseTerrain",
                            "Position": {
                              "$id": "8",
                              "X": 25000.0,
                              "Y": 26000.0
                            },
                            "Ports": {
                              "$id": "9",
                              "$values": [
                                {
                                  "$id": "11",
                                  "Name": "In",
                                  "Type": "PrimaryIn",
                                  "IsExporting": true,
                                  "Parent": {
                                    "$ref": "7"
                                  }
                                },
                                {
                                  "$id": "12",
                                  "Name": "Out",
                                  "Type": "PrimaryOut",
                                  "IsExporting": true,
                                  "Parent": {
                                    "$ref": "7"
                                  }
                                }
                              ]
                            },
                            "Modifiers": {
                              "$id": "10",
                              "$values": []
                            }
                          },
                          "101": {
                            "$id": "13",
                            "$type": "QuadSpinner.Gaea.Nodes.Erosion2, Gaea.Nodes",
                            "Duration": 0.15,
                            "Downcutting": 0.3,
                            "ErosionScale": 5000.0,
                            "Seed": 12345,
                            "BedLoadDischargeAmount": 0.0,
                            "BedLoadDischargeAngle": 0.0,
                            "CoarseSedimentsDischargeAmount": 0.0,
                            "CoarseSedimentsDischargeAngle": 0.0,
                            "SuspendedLoadDischargeAmount": 0.0,
                            "SuspendedLoadDischargeAngle": 0.0,
                            "Shape": 0.5,
                            "ShapeDetailScale": 0.5,
                            "ShapeSharpness": 0.5,
                            "Id": 101,
                            "Name": "NaturalErosion",
                            "Position": {
                              "$id": "14",
                              "X": 25500.0,
                              "Y": 26000.0
                            },
                            "Ports": {
                              "$id": "15",
                              "$values": [
                                {
                                  "$id": "17",
                                  "Name": "In",
                                  "Type": "PrimaryIn",
                                  "Record": {
                                    "$id": "18",
                                    "From": 100,
                                    "To": 101,
                                    "FromPort": "Out",
                                    "ToPort": "In",
                                    "IsValid": true
                                  },
                                  "IsExporting": true,
                                  "Parent": {
                                    "$ref": "13"
                                  }
                                },
                                {
                                  "$id": "19",
                                  "Name": "Out",
                                  "Type": "PrimaryOut",
                                  "IsExporting": true,
                                  "Parent": {
                                    "$ref": "13"
                                  }
                                },
                                {
                                  "$id": "20",
                                  "Name": "Flow",
                                  "Type": "Out",
                                  "IsExporting": true,
                                  "Parent": {
                                    "$ref": "13"
                                  }
                                },
                                {
                                  "$id": "21",
                                  "Name": "Wear",
                                  "Type": "Out",
                                  "IsExporting": true,
                                  "Parent": {
                                    "$ref": "13"
                                  }
                                },
                                {
                                  "$id": "22",
                                  "Name": "Deposits",
                                  "Type": "Out",
                                  "IsExporting": true,
                                  "Parent": {
                                    "$ref": "13"
                                  }
                                },
                                {
                                  "$id": "23",
                                  "Name": "Mask",
                                  "Type": "In",
                                  "IsExporting": true,
                                  "Parent": {
                                    "$ref": "13"
                                  }
                                }
                              ]
                            },
                            "Modifiers": {
                              "$id": "16",
                              "$values": []
                            }
                          },
                          "102": {
                            "$id": "24",
                            "$type": "QuadSpinner.Gaea.Nodes.TextureBase, Gaea.Nodes",
                            "Slope": 0.5,
                            "Scale": 0.5,
                            "Soil": 0.5,
                            "Patches": 0.5,
                            "Chaos": 0.5,
                            "Seed": 0,
                            "Id": 102,
                            "Name": "BaseTexture",
                            "Position": {
                              "$id": "25",
                              "X": 26000.0,
                              "Y": 26000.0
                            },
                            "Ports": {
                              "$id": "26",
                              "$values": [
                                {
                                  "$id": "28",
                                  "Name": "In",
                                  "Type": "PrimaryIn",
                                  "Record": {
                                    "$id": "29",
                                    "From": 101,
                                    "To": 102,
                                    "FromPort": "Out",
                                    "ToPort": "In",
                                    "IsValid": true
                                  },
                                  "IsExporting": true,
                                  "Parent": {
                                    "$ref": "24"
                                  }
                                },
                                {
                                  "$id": "30",
                                  "Name": "Out",
                                  "Type": "PrimaryOut",
                                  "IsExporting": true,
                                  "Parent": {
                                    "$ref": "24"
                                  }
                                }
                              ]
                            },
                            "IsMaskable": true,
                            "Modifiers": {
                              "$id": "27",
                              "$values": []
                            }
                          },
                          "103": {
                            "$id": "31",
                            "$type": "QuadSpinner.Gaea.Nodes.SatMap, Gaea.Nodes",
                            "Library": "Rock",
                            "LibraryItem": 0,
                            "Randomize": false,
                            "Range": {
                              "$id": "32",
                              "X": 0.5,
                              "Y": 0.5
                            },
                            "Bias": 0.5,
                            "Enhance": "None",
                            "Reverse": false,
                            "Rough": "None",
                            "Hue": 0.0,
                            "Saturation": 0.0,
                            "Lightness": 0.0,
                            "Id": 103,
                            "Name": "ColorMap",
                            "NodeSize": "Standard",
                            "Position": {
                              "$id": "33",
                              "X": 26500.0,
                              "Y": 26000.0
                            },
                            "Ports": {
                              "$id": "34",
                              "$values": [
                                {
                                  "$id": "36",
                                  "Name": "In",
                                  "Type": "PrimaryIn, Required",
                                  "Record": {
                                    "$id": "37",
                                    "From": 102,
                                    "To": 103,
                                    "FromPort": "Out",
                                    "ToPort": "In",
                                    "IsValid": true
                                  },
                                  "IsExporting": true,
                                  "Parent": {
                                    "$ref": "31"
                                  }
                                },
                                {
                                  "$id": "38",
                                  "Name": "Out",
                                  "Type": "PrimaryOut",
                                  "IsExporting": true,
                                  "Parent": {
                                    "$ref": "31"
                                  }
                                }
                              ]
                            },
                            "Modifiers": {
                              "$id": "35",
                              "$values": []
                            }
                          },
                          "104": {
                            "$id": "39",
                            "$type": "QuadSpinner.Gaea.Nodes.Export, Gaea.Nodes",
                            "Id": 104,
                            "Name": "TerrainExport",
                            "NodeSize": "Standard",
                            "Position": {
                              "$id": "40",
                              "X": 27000.0,
                              "Y": 26000.0
                            },
                            "SaveDefinition": {
                              "$id": "41",
                              "Node": 104,
                              "Filename": "TerrainExport",
                              "Format": "EXR",
                              "IsEnabled": true
                            },
                            "Ports": {
                              "$id": "42",
                              "$values": [
                                {
                                  "$id": "44",
                                  "Name": "In",
                                  "Type": "PrimaryIn, Required",
                                  "Record": {
                                    "$id": "45",
                                    "From": 103,
                                    "To": 104,
                                    "FromPort": "Out",
                                    "ToPort": "In",
                                    "IsValid": true
                                  },
                                  "IsExporting": true,
                                  "Parent": {
                                    "$ref": "39"
                                  }
                                },
                                {
                                  "$id": "46",
                                  "Name": "Out",
                                  "Type": "PrimaryOut",
                                  "IsExporting": true,
                                  "Parent": {
                                    "$ref": "39"
                                  }
                                }
                              ]
                            },
                            "Modifiers": {
                              "$id": "43",
                              "$values": []
                            }
                          }
                        },
                        "Groups": {
                          "$id": "47"
                        },
                        "Notes": {
                          "$id": "48"
                        },
                        "GraphTabs": {
                          "$id": "49",
                          "$values": [
                            {
                              "$id": "50",
                              "Name": "Graph 1",
                              "Color": "Brass",
                              "ZoomFactor": 0.5338687202362516,
                              "ViewportLocation": {
                                "$id": "51",
                                "X": 25531.445,
                                "Y": 25791.812
                              }
                            }
                          ]
                        },
                        "Width": 5000.0,
                        "Height": 2500.0,
                        "Ratio": 0.5
                      },
                      "Automation": {
                        "$id": "52",
                        "Bindings": {
                          "$id": "53",
                          "$values": []
                        },
                        "Variables": {
                          "$id": "54"
                        },
                        "BoundProperties": {
                          "$id": "55",
                          "$values": []
                        }
                      },
                      "BuildDefinition": {
                        "$id": "56",
                        "Destination": "<Builds>\\[Filename]\\[+++]",
                        "Resolution": 2048,
                        "BakeResolution": 2048,
                        "TileResolution": 1024,
                        "BucketResolution": 2048,
                        "BucketCount": 1,
                        "WorldResolution": 2048,
                        "NumberOfTiles": 1,
                        "TotalTiles": 1,
                        "BucketSizeWithMargin": 3072,
                        "EdgeBlending": 0.25,
                        "EdgeSize": 512,
                        "TileZeroIndex": true,
                        "TilePattern": "_y%Y%_x%X%",
                        "OrganizeFiles": "NodeSubFolder",
                        "PostBuildScript": "",
                        "Regions": {
                          "$id": "57",
                          "$values": []
                        }
                      },
                      "State": {
                        "$id": "58",
                        "BakeResolution": 2048,
                        "PreviewResolution": 512,
                        "SelectedNode": 100,
                        "LockedNode": null,
                        "NodeBookmarks": {
                          "$id": "59",
                          "$values": []
                        },
                        "Viewport": {
                          "$id": "60",
                          "RenderMode": "Realistic",
                          "SunAltitude": 33.0,
                          "SunAzimuth": 45.0,
                          "SunIntensity": 1.0,
                          "AmbientOcclusion": true,
                          "Shadows": true,
                          "AirDensity": 1.0,
                          "AmbientIntensity": 1.0,
                          "Exposure": 1.0,
                          "FogDensity": 0.2,
                          "GroundBrightness": 0.8,
                          "Haze": 1.0,
                          "Ozone": 1.0,
                          "Camera": {
                            "$id": "61"
                          }
                        }
                      }
                    }
                  ]
                },
                "Id": "8c3f61a5",
                "Branch": 1,
                "Metadata": {
                  "$id": "62",
                  "Name": "test_connectivity_20250721_175151",
                  "Description": "Created by Gaea2 MCP Server",
                  "Version": "",
                  "Owner": "",
                  "DateCreated": "2025-07-21 17:51:52Z",
                  "DateLastBuilt": "2025-07-21 17:51:52Z",
                  "DateLastSaved": "2025-07-21 17:51:52Z"
                }
              },
              "validation_result": {
                "success": true,
                "result": {
                  "valid": true,
                  "fixes_applied": [],
                  "errors": [],
                  "workflow": {
                    "nodes": [
                      {
                        "id": 100,
                        "type": "Mountain",
                        "name": "BaseTerrain",
                        "position": {
                          "x": 25000,
                          "y": 26000
                        },
                        "properties": {
                          "Scale": 1.0,
                          "Height": 0.7,
                          "Style": "Alpine",
                          "Bulk": "Medium",
                          "ReduceDetails": false,
                          "Seed": 0,
                          "X": 0.0,
                          "Y": 0.0
                        }
                      },
                      {
                        "id": 101,
                        "type": "Erosion2",
                        "name": "NaturalErosion",
                        "position": {
                          "x": 25500,
                          "y": 26000
                        },
                        "properties": {
                          "Duration": 0.15,
                          "Downcutting": 0.3,
                          "ErosionScale": 5000.0,
                          "Seed": 12345,
                          "BedLoadDischargeAmount": 0.0,
                          "BedLoadDischargeAngle": 0.0,
                          "CoarseSedimentsDischargeAmount": 0.0,
                          "CoarseSedimentsDischargeAngle": 0.0,
                          "SuspendedLoadDischargeAmount": 0.0,
                          "SuspendedLoadDischargeAngle": 0.0,
                          "Shape": 0.5,
                          "ShapeDetailScale": 0.5,
                          "ShapeSharpness": 0.5
                        }
                      },
                      {
                        "id": 102,
                        "type": "TextureBase",
                        "name": "BaseTexture",
                        "position": {
                          "x": 26000,
                          "y": 26000
                        },
                        "properties": {
                          "Slope": 0.5,
                          "Scale": 0.5,
                          "Soil": 0.5,
                          "Patches": 0.5,
                          "Chaos": 0.5,
                          "Seed": 0
                        }
                      },
                      {
                        "id": 103,
                        "type": "SatMap",
                        "name": "ColorMap",
                        "position": {
                          "x": 26500,
                          "y": 26000
                        },
                        "properties": {
                          "Library": "Rock",
                          "LibraryItem": 0,
                          "Randomize": false,
                          "Range": {
                            "X": 0.5,
                            "Y": 0.5
                          },
                          "Bias": 0.5,
                          "Enhance": "None",
                          "Reverse": false,
                          "Rough": "None",
                          "Hue": 0.0,
                          "Saturation": 0.0,
                          "Lightness": 0.0
                        }
                      },
                      {
                        "id": 104,
                        "type": "Export",
                        "name": "TerrainExport",
                        "position": {
                          "x": 27000,
                          "y": 26000
                        },
                        "properties": {},
                        "save_definition": {
                          "filename": "terrain_output",
                          "format": "EXR",
                          "enabled": true
                        },
                        "_export_format": "EXR",
                        "_export_filename": "TerrainExport"
                      }
                    ],
                    "connections": [
                      {
                        "from_node": 100,
                        "to_node": 101,
                        "from_port": "Out",
                        "to_port": "In"
                      },
                      {
                        "from_node": 101,
                        "to_node": 102,
                        "from_port": "Out",
                        "to_port": "In"
                      },
                      {
                        "from_node": 102,
                        "to_node": 103,
                        "from_port": "Out",
                        "to_port": "In"
                      },
                      {
                        "from_node": 103,
                        "to_node": 104,
                        "from_port": "Out",
                        "to_port": "In"
                      }
                    ]
                  }
                },
                "results": {
                  "original_workflow": {
                    "nodes": [
                      {
                        "id": 100,
                        "type": "Mountain",
                        "name": "BaseTerrain",
                        "position": {
                          "x": 25000,
                          "y": 26000
                        },
                        "properties": {
                          "Scale": 1.0,
                          "Height": 0.7,
                          "Style": "Alpine",
                          "Bulk": "Medium",
                          "ReduceDetails": false,
                          "Seed": 0,
                          "X": 0.0,
                          "Y": 0.0
                        }
                      },
                      {
                        "id": 101,
                        "type": "Erosion2",
                        "name": "NaturalErosion",
                        "position": {
                          "x": 25500,
                          "y": 26000
                        },
                        "properties": {
                          "Duration": 0.15,
                          "Downcutting": 0.3,
                          "ErosionScale": 5000.0,
                          "Seed": 12345,
                          "BedLoadDischargeAmount": 0.0,
                          "BedLoadDischargeAngle": 0.0,
                          "CoarseSedimentsDischargeAmount": 0.0,
                          "CoarseSedimentsDischargeAngle": 0.0,
                          "SuspendedLoadDischargeAmount": 0.0,
                          "SuspendedLoadDischargeAngle": 0.0,
                          "Shape": 0.5,
                          "ShapeDetailScale": 0.5,
                          "ShapeSharpness": 0.5
                        }
                      },
                      {
                        "id": 102,
                        "type": "TextureBase",
                        "name": "BaseTexture",
                        "position": {
                          "x": 26000,
                          "y": 26000
                        },
                        "properties": {
                          "Slope": 0.5,
                          "Scale": 0.5,
                          "Soil": 0.5,
                          "Patches": 0.5,
                          "Chaos": 0.5,
                          "Seed": 0
                        }
                      },
                      {
                        "id": 103,
                        "type": "SatMap",
                        "name": "ColorMap",
                        "position": {
                          "x": 26500,
                          "y": 26000
                        },
                        "properties": {
                          "Library": "Rock",
                          "LibraryItem": 0,
                          "Randomize": false,
                          "Range": {
                            "X": 0.5,
                            "Y": 0.5
                          },
                          "Bias": 0.5,
                          "Enhance": "None",
                          "Reverse": false,
                          "Rough": "None",
                          "Hue": 0.0,
                          "Saturation": 0.0,
                          "Lightness": 0.0
                        }
                      },
                      {
                        "id": 104,
                        "type": "Export",
                        "name": "TerrainExport",
                        "position": {
                          "x": 27000,
                          "y": 26000
                        },
                        "properties": {},
                        "save_definition": {
                          "filename": "terrain_output",
                          "format": "EXR",
                          "enabled": true
                        },
                        "_export_format": "EXR",
                        "_export_filename": "TerrainExport"
                      }
                    ],
                    "connections": [
                      {
                        "from_node": 100,
                        "to_node": 101,
                        "from_port": "Out",
                        "to_port": "In"
                      },
                      {
                        "from_node": 101,
                        "to_node": 102,
                        "from_port": "Out",
                        "to_port": "In"
                      },
                      {
                        "from_node": 102,
                        "to_node": 103,
                        "from_port": "Out",
                        "to_port": "In"
                      },
                      {
                        "from_node": 103,
                        "to_node": 104,
                        "from_port": "Out",
                        "to_port": "In"
                      }
                    ]
                  },
                  "validation_results": {
                    "properties": {
                      "valid": true,
                      "errors": []
                    },
                    "connections": {
                      "valid": true,
                      "errors": []
                    },
                    "structure": {
                      "valid": true,
                      "errors": []
                    }
                  },
                  "fixes_applied": [],
                  "final_workflow": {
                    "nodes": [
                      {
                        "id": 100,
                        "type": "Mountain",
                        "name": "BaseTerrain",
                        "position": {
                          "x": 25000,
                          "y": 26000
                        },
                        "properties": {
                          "Scale": 1.0,
                          "Height": 0.7,
                          "Style": "Alpine",
                          "Bulk": "Medium",
                          "ReduceDetails": false,
                          "Seed": 0,
                          "X": 0.0,
                          "Y": 0.0
                        }
                      },
                      {
                        "id": 101,
                        "type": "Erosion2",
                        "name": "NaturalErosion",
                        "position": {
                          "x": 25500,
                          "y": 26000
                        },
                        "properties": {
                          "Duration": 0.15,
                          "Downcutting": 0.3,
                          "ErosionScale": 5000.0,
                          "Seed": 12345,
                          "BedLoadDischargeAmount": 0.0,
                          "BedLoadDischargeAngle": 0.0,
                          "CoarseSedimentsDischargeAmount": 0.0,
                          "CoarseSedimentsDischargeAngle": 0.0,
                          "SuspendedLoadDischargeAmount": 0.0,
                          "SuspendedLoadDischargeAngle": 0.0,
                          "Shape": 0.5,
                          "ShapeDetailScale": 0.5,
                          "ShapeSharpness": 0.5
                        }
                      },
                      {
                        "id": 102,
                        "type": "TextureBase",
                        "name": "BaseTexture",
                        "position": {
                          "x": 26000,
                          "y": 26000
                        },
                        "properties": {
                          "Slope": 0.5,
                          "Scale": 0.5,
                          "Soil": 0.5,
                          "Patches": 0.5,
                          "Chaos": 0.5,
                          "Seed": 0
                        }
                      },
                      {
                        "id": 103,
                        "type": "SatMap",
                        "name": "ColorMap",
                        "position": {
                          "x": 26500,
                          "y": 26000
                        },
                        "properties": {
                          "Library": "Rock",
                          "LibraryItem": 0,
                          "Randomize": false,
                          "Range": {
                            "X": 0.5,
                            "Y": 0.5
                          },
                          "Bias": 0.5,
                          "Enhance": "None",
                          "Reverse": false,
                          "Rough": "None",
                          "Hue": 0.0,
                          "Saturation": 0.0,
                          "Lightness": 0.0
                        }
                      },
                      {
                        "id": 104,
                        "type": "Export",
                        "name": "TerrainExport",
                        "position": {
                          "x": 27000,
                          "y": 26000
                        },
                        "properties": {},
                        "save_definition": {
                          "filename": "terrain_output",
                          "format": "EXR",
                          "enabled": true
                        },
                        "_export_format": "EXR",
                        "_export_filename": "TerrainExport"
                      }
                    ],
                    "connections": [
                      {
                        "from_node": 100,
                        "to_node": 101,
                        "from_port": "Out",
                        "to_port": "In"
                      },
                      {
                        "from_node": 101,
                        "to_node": 102,
                        "from_port": "Out",
                        "to_port": "In"
                      },
                      {
                        "from_node": 102,
                        "to_node": 103,
                        "from_port": "Out",
                        "to_port": "In"
                      },
                      {
                        "from_node": 103,
                        "to_node": 104,
                        "from_port": "Out",
                        "to_port": "In"
                      }
                    ]
                  },
                  "is_valid": true
                }
              },
              "template_used": "basic_terrain",
              "message": "Project created from template 'basic_terrain'"
            }
          }
        ],
        [
          "validation",
          {
            "success": true,
            "result": {
              "success": true,
              "result": {
                "valid": true,
                "fixes_applied": [],
                "errors": [],
                "workflow": {
                  "nodes": [
                    {
                      "id": "1",
                      "node": "Mountain",
                      "position": {
                        "X": 0,
                        "Y": 0
                      }
                    },
                    {
                      "id": "2",
                      "node": "Export",
                      "position": {
                        "X": 1,
                        "Y": 0
                      }
                    }
                  ],
                  "connections": [
                    {
                      "source": "1",
                      "source_port": "Out",
                      "target": "2",
                      "target_port": "In"
                    }
                  ]
                }
              },
              "results": {
                "original_workflow": {
                  "nodes": [
                    {
                      "id": "1",
                      "node": "Mountain",
                      "position": {
                        "X": 0,
                        "Y": 0
                      }
                    },
                    {
                      "id": "2",
                      "node": "Export",
                      "position": {
                        "X": 1,
                        "Y": 0
                      }
                    }
                  ],
                  "connections": [
                    {
                      "source": "1",
                      "source_port": "Out",
                      "target": "2",
                      "target_port": "In"
                    }
                  ]
                },
                "validation_results": {
                  "properties": {
                    "valid": true,
                    "errors": []
                  },
                  "connections": {
                    "valid": true,
                    "errors": []
                  },
                  "structure": {
                    "valid": true,
                    "errors": []
                  }
                },
                "fixes_applied": [],
                "final_workflow": {
                  "nodes": [
                    {
                      "id": "1",
                      "node": "Mountain",
                      "position": {
                        "X": 0,
                        "Y": 0
                      }
                    },
                    {
                      "id": "2",
                      "node": "Export",
                      "position": {
                        "X": 1,
                        "Y": 0
                      }
                    }
                  ],
                  "connections": [
                    {
                      "source": "1",
                      "source_port": "Out",
                      "target": "2",
                      "target_port": "In"
                    }
                  ]
                },
                "is_valid": true
              }
            }
          }
        ],
        [
          "error_handling",
          {
            "success": true,
            "error_handled": true
          }
        ]
      ],
      "success": true
    },
    "framework_integration": {
      "exit_code": 1,
      "total": 15,
      "passed": 0,
      "failed": 15,
      "skipped": 0,
      "duration": 0.4770216941833496,
      "tests": [
        {
          "nodeid": "tests/gaea2/test_framework_integration.py::TestSuccessfulOperations::test_create_basic_terrain",
          "lineno": 96,
          "outcome": "failed",
          "keywords": [
            "test_create_basic_terrain",
            "asyncio",
            "pytestmark",
            "TestSuccessfulOperations",
            "test_framework_integration.py",
            "gaea2",
            "tests",
            "template-repo",
            ""
          ],
          "setup": {
            "duration": 0.0003673640312626958,
            "outcome": "passed"
          },
          "call": {
            "duration": 0.0002524130395613611,
            "outcome": "failed",
            "crash": {
              "path": "/usr/lib/python3.10/asyncio/base_events.py",
              "lineno": 584,
              "message": "RuntimeError: This event loop is already running"
            },
            "traceback": [
              {
                "path": "../../../.local/lib/python3.10/site-packages/pytest_asyncio/plugin.py",
                "lineno": 508,
                "message": "in runtest"
              },
              {
                "path": "../../../.local/lib/python3.10/site-packages/pytest_asyncio/plugin.py",
                "lineno": 773,
                "message": "in inner"
              },
              {
                "path": "/usr/lib/python3.10/asyncio/base_events.py",
                "lineno": 625,
                "message": "in run_until_complete"
              },
              {
                "path": "/usr/lib/python3.10/asyncio/base_events.py",
                "lineno": 584,
                "message": "in _check_running"
              }
            ],
            "longrepr": "../../../.local/lib/python3.10/site-packages/pytest_asyncio/plugin.py:508: in runtest\n    super().runtest()\n../../../.local/lib/python3.10/site-packages/pytest_asyncio/plugin.py:773: in inner\n    _loop.run_until_complete(task)\n/usr/lib/python3.10/asyncio/base_events.py:625: in run_until_complete\n    self._check_running()\n/usr/lib/python3.10/asyncio/base_events.py:584: in _check_running\n    raise RuntimeError('This event loop is already running')\nE   RuntimeError: This event loop is already running"
          },
          "teardown": {
            "duration": 0.00035777402808889747,
            "outcome": "passed"
          }
        },
        {
          "nodeid": "tests/gaea2/test_framework_integration.py::TestSuccessfulOperations::test_validate_workflow",
          "lineno": 111,
          "outcome": "failed",
          "keywords": [
            "test_validate_workflow",
            "asyncio",
            "pytestmark",
            "TestSuccessfulOperations",
            "test_framework_integration.py",
            "gaea2",
            "tests",
            "template-repo",
            ""
          ],
          "setup": {
            "duration": 0.0003231230075471103,
            "outcome": "passed"
          },
          "call": {
            "duration": 0.00016432104166597128,
            "outcome": "failed",
            "crash": {
              "path": "/usr/lib/python3.10/asyncio/base_events.py",
              "lineno": 584,
              "message": "RuntimeError: This event loop is already running"
            },
            "traceback": [
              {
                "path": "../../../.local/lib/python3.10/site-packages/pytest_asyncio/plugin.py",
                "lineno": 508,
                "message": "in runtest"
              },
              {
                "path": "../../../.local/lib/python3.10/site-packages/pytest_asyncio/plugin.py",
                "lineno": 773,
                "message": "in inner"
              },
              {
                "path": "/usr/lib/python3.10/asyncio/base_events.py",
                "lineno": 625,
                "message": "in run_until_complete"
              },
              {
                "path": "/usr/lib/python3.10/asyncio/base_events.py",
                "lineno": 584,
                "message": "in _check_running"
              }
            ],
            "longrepr": "../../../.local/lib/python3.10/site-packages/pytest_asyncio/plugin.py:508: in runtest\n    super().runtest()\n../../../.local/lib/python3.10/site-packages/pytest_asyncio/plugin.py:773: in inner\n    _loop.run_until_complete(task)\n/usr/lib/python3.10/asyncio/base_events.py:625: in run_until_complete\n    self._check_running()\n/usr/lib/python3.10/asyncio/base_events.py:584: in _check_running\n    raise RuntimeError('This event loop is already running')\nE   RuntimeError: This event loop is already running"
          },
          "teardown": {
            "duration": 0.0003196130273863673,
            "outcome": "passed"
          }
        },
        {
          "nodeid": "tests/gaea2/test_framework_integration.py::TestSuccessfulOperations::test_analyze_patterns",
          "lineno": 174,
          "outcome": "failed",
          "keywords": [
            "test_analyze_patterns",
            "asyncio",
            "pytestmark",
            "TestSuccessfulOperations",
            "test_framework_integration.py",
            "gaea2",
            "tests",
            "template-repo",
            ""
          ],
          "setup": {
            "duration": 0.00028267299057915807,
            "outcome": "passed"
          },
          "call": {
            "duration": 0.0001620109542272985,
            "outcome": "failed",
            "crash": {
              "path": "/usr/lib/python3.10/asyncio/base_events.py",
              "lineno": 584,
              "message": "RuntimeError: This event loop is already running"
            },
            "traceback": [
              {
                "path": "../../../.local/lib/python3.10/site-packages/pytest_asyncio/plugin.py",
                "lineno": 508,
                "message": "in runtest"
              },
              {
                "path": "../../../.local/lib/python3.10/site-packages/pytest_asyncio/plugin.py",
                "lineno": 773,
                "message": "in inner"
              },
              {
                "path": "/usr/lib/python3.10/asyncio/base_events.py",
                "lineno": 625,
                "message": "in run_until_complete"
              },
              {
                "path": "/usr/lib/python3.10/asyncio/base_events.py",
                "lineno": 584,
                "message": "in _check_running"
              }
            ],
            "longrepr": "../../../.local/lib/python3.10/site-packages/pytest_asyncio/plugin.py:508: in runtest\n    super().runtest()\n../../../.local/lib/python3.10/site-packages/pytest_asyncio/plugin.py:773: in inner\n    _loop.run_until_complete(task)\n/usr/lib/python3.10/asyncio/base_events.py:625: in run_until_complete\n    self._check_running()\n/usr/lib/python3.10/asyncio/base_events.py:584: in _check_running\n    raise RuntimeError('This event loop is already running')\nE   RuntimeError: This event loop is already running"
          },
          "teardown": {
            "duration": 0.00020186201436445117,
            "outcome": "passed"
          }
        },
        {
          "nodeid": "tests/gaea2/test_framework_integration.py::TestSuccessfulOperations::test_node_suggestions",
          "lineno": 223,
          "outcome": "failed",
          "keywords": [
            "test_node_suggestions",
            "asyncio",
            "pytestmark",
            "TestSuccessfulOperations",
            "test_framework_integration.py",
            "gaea2",
            "tests",
            "template-repo",
            ""
          ],
          "setup": {
            "duration": 0.00025535200256854296,
            "outcome": "passed"
          },
          "call": {
            "duration": 0.0002177419955842197,
            "outcome": "failed",
            "crash": {
              "path": "/usr/lib/python3.10/asyncio/base_events.py",
              "lineno": 584,
              "message": "RuntimeError: This event loop is already running"
            },
            "traceback": [
              {
                "path": "../../../.local/lib/python3.10/site-packages/pytest_asyncio/plugin.py",
                "lineno": 508,
                "message": "in runtest"
              },
              {
                "path": "../../../.local/lib/python3.10/site-packages/pytest_asyncio/plugin.py",
                "lineno": 773,
                "message": "in inner"
              },
              {
                "path": "/usr/lib/python3.10/asyncio/base_events.py",
                "lineno": 625,
                "message": "in run_until_complete"
              },
              {
                "path": "/usr/lib/python3.10/asyncio/base_events.py",
                "lineno": 584,
                "message": "in _check_running"
              }
            ],
            "longrepr": "../../../.local/lib/python3.10/site-packages/pytest_asyncio/plugin.py:508: in runtest\n    super().runtest()\n../../../.local/lib/python3.10/site-packages/pytest_asyncio/plugin.py:773: in inner\n    _loop.run_until_complete(task)\n/usr/lib/python3.10/asyncio/base_events.py:625: in run_until_complete\n    self._check_running()\n/usr/lib/python3.10/asyncio/base_events.py:584: in _check_running\n    raise RuntimeError('This event loop is already running')\nE   RuntimeError: This event loop is already running"
          },
          "teardown": {
            "duration": 0.00019946199608966708,
            "outcome": "passed"
          }
        },
        {
          "nodeid": "tests/gaea2/test_framework_integration.py::TestExpectedFailures::test_invalid_template_name",
          "lineno": 247,
          "outcome": "failed",
          "keywords": [
            "test_invalid_template_name",
            "asyncio",
            "pytestmark",
            "TestExpectedFailures",
            "test_framework_integration.py",
            "gaea2",
            "tests",
            "template-repo",
            ""
          ],
          "setup": {
            "duration": 0.0002493029460310936,
            "outcome": "passed"
          },
          "call": {
            "duration": 0.00015829195035621524,
            "outcome": "failed",
            "crash": {
              "path": "/usr/lib/python3.10/asyncio/base_events.py",
              "lineno": 584,
              "message": "RuntimeError: This event loop is already running"
            },
            "traceback": [
              {
                "path": "../../../.local/lib/python3.10/site-packages/pytest_asyncio/plugin.py",
                "lineno": 508,
                "message": "in runtest"
              },
              {
                "path": "../../../.local/lib/python3.10/site-packages/pytest_asyncio/plugin.py",
                "lineno": 773,
                "message": "in inner"
              },
              {
                "path": "/usr/lib/python3.10/asyncio/base_events.py",
                "lineno": 625,
                "message": "in run_until_complete"
              },
              {
                "path": "/usr/lib/python3.10/asyncio/base_events.py",
                "lineno": 584,
                "message": "in _check_running"
              }
            ],
            "longrepr": "../../../.local/lib/python3.10/site-packages/pytest_asyncio/plugin.py:508: in runtest\n    super().runtest()\n../../../.local/lib/python3.10/site-packages/pytest_asyncio/plugin.py:773: in inner\n    _loop.run_until_complete(task)\n/usr/lib/python3.10/asyncio/base_events.py:625: in run_until_complete\n    self._check_running()\n/usr/lib/python3.10/asyncio/base_events.py:584: in _check_running\n    raise RuntimeError('This event loop is already running')\nE   RuntimeError: This event loop is already running"
          },
          "teardown": {
            "duration": 0.00022547197295352817,
            "outcome": "passed"
          }
        },
        {
          "nodeid": "tests/gaea2/test_framework_integration.py::TestExpectedFailures::test_invalid_node_type",
          "lineno": 258,
          "outcome": "failed",
          "keywords": [
            "test_invalid_node_type",
            "asyncio",
            "pytestmark",
            "TestExpectedFailures",
            "test_framework_integration.py",
            "gaea2",
            "tests",
            "template-repo",
            ""
          ],
          "setup": {
            "duration": 0.00031838298309594393,
            "outcome": "passed"
          },
          "call": {
            "duration": 0.0001576110371388495,
            "outcome": "failed",
            "crash": {
              "path": "/usr/lib/python3.10/asyncio/base_events.py",
              "lineno": 584,
              "message": "RuntimeError: This event loop is already running"
            },
            "traceback": [
              {
                "path": "../../../.local/lib/python3.10/site-packages/pytest_asyncio/plugin.py",
                "lineno": 508,
                "message": "in runtest"
              },
              {
                "path": "../../../.local/lib/python3.10/site-packages/pytest_asyncio/plugin.py",
                "lineno": 773,
                "message": "in inner"
              },
              {
                "path": "/usr/lib/python3.10/asyncio/base_events.py",
                "lineno": 625,
                "message": "in run_until_complete"
              },
              {
                "path": "/usr/lib/python3.10/asyncio/base_events.py",
                "lineno": 584,
                "message": "in _check_running"
              }
            ],
            "longrepr": "../../../.local/lib/python3.10/site-packages/pytest_asyncio/plugin.py:508: in runtest\n    super().runtest()\n../../../.local/lib/python3.10/site-packages/pytest_asyncio/plugin.py:773: in inner\n    _loop.run_until_complete(task)\n/usr/lib/python3.10/asyncio/base_events.py:625: in run_until_complete\n    self._check_running()\n/usr/lib/python3.10/asyncio/base_events.py:584: in _check_running\n    raise RuntimeError('This event loop is already running')\nE   RuntimeError: This event loop is already running"
          },
          "teardown": {
            "duration": 0.00025853299302980304,
            "outcome": "passed"
          }
        },
        {
          "nodeid": "tests/gaea2/test_framework_integration.py::TestExpectedFailures::test_circular_connections",
          "lineno": 280,
          "outcome": "failed",
          "keywords": [
            "test_circular_connections",
            "asyncio",
            "pytestmark",
            "TestExpectedFailures",
            "test_framework_integration.py",
            "gaea2",
            "tests",
            "template-repo",
            ""
          ],
          "setup": {
            "duration": 0.00027951301308348775,
            "outcome": "passed"
          },
          "call": {
            "duration": 0.00016244204016402364,
            "outcome": "failed",
            "crash": {
              "path": "/usr/lib/python3.10/asyncio/base_events.py",
              "lineno": 584,
              "message": "RuntimeError: This event loop is already running"
            },
            "traceback": [
              {
                "path": "../../../.local/lib/python3.10/site-packages/pytest_asyncio/plugin.py",
                "lineno": 508,
                "message": "in runtest"
              },
              {
                "path": "../../../.local/lib/python3.10/site-packages/pytest_asyncio/plugin.py",
                "lineno": 773,
                "message": "in inner"
              },
              {
                "path": "/usr/lib/python3.10/asyncio/base_events.py",
                "lineno": 625,
                "message": "in run_until_complete"
              },
              {
                "path": "/usr/lib/python3.10/asyncio/base_events.py",
                "lineno": 584,
                "message": "in _check_running"
              }
            ],
            "longrepr": "../../../.local/lib/python3.10/site-packages/pytest_asyncio/plugin.py:508: in runtest\n    super().runtest()\n../../../.local/lib/python3.10/site-packages/pytest_asyncio/plugin.py:773: in inner\n    _loop.run_until_complete(task)\n/usr/lib/python3.10/asyncio/base_events.py:625: in run_until_complete\n    self._check_running()\n/usr/lib/python3.10/asyncio/base_events.py:584: in _check_running\n    raise RuntimeError('This event loop is already running')\nE   RuntimeError: This event loop is already running"
          },
          "teardown": {
            "duration": 0.0002323619555681944,
            "outcome": "passed"
          }
        },
        {
          "nodeid": "tests/gaea2/test_framework_integration.py::TestEdgeCases::test_empty_workflow",
          "lineno": 329,
          "outcome": "failed",
          "keywords": [
            "test_empty_workflow",
            "asyncio",
            "pytestmark",
            "TestEdgeCases",
            "test_framework_integration.py",
            "gaea2",
            "tests",
            "template-repo",
            ""
          ],
          "setup": {
            "duration": 0.00027870299527421594,
            "outcome": "passed"
          },
          "call": {
            "duration": 0.00015824101865291595,
            "outcome": "failed",
            "crash": {
              "path": "/usr/lib/python3.10/asyncio/base_events.py",
              "lineno": 584,
              "message": "RuntimeError: This event loop is already running"
            },
            "traceback": [
              {
                "path": "../../../.local/lib/python3.10/site-packages/pytest_asyncio/plugin.py",
                "lineno": 508,
                "message": "in runtest"
              },
              {
                "path": "../../../.local/lib/python3.10/site-packages/pytest_asyncio/plugin.py",
                "lineno": 773,
                "message": "in inner"
              },
              {
                "path": "/usr/lib/python3.10/asyncio/base_events.py",
                "lineno": 625,
                "message": "in run_until_complete"
              },
              {
                "path": "/usr/lib/python3.10/asyncio/base_events.py",
                "lineno": 584,
                "message": "in _check_running"
              }
            ],
            "longrepr": "../../../.local/lib/python3.10/site-packages/pytest_asyncio/plugin.py:508: in runtest\n    super().runtest()\n../../../.local/lib/python3.10/site-packages/pytest_asyncio/plugin.py:773: in inner\n    _loop.run_until_complete(task)\n/usr/lib/python3.10/asyncio/base_events.py:625: in run_until_complete\n    self._check_running()\n/usr/lib/python3.10/asyncio/base_events.py:584: in _check_running\n    raise RuntimeError('This event loop is already running')\nE   RuntimeError: This event loop is already running"
          },
          "teardown": {
            "duration": 0.0002072919742204249,
            "outcome": "passed"
          }
        },
        {
          "nodeid": "tests/gaea2/test_framework_integration.py::TestEdgeCases::test_maximum_complexity",
          "lineno": 341,
          "outcome": "failed",
          "keywords": [
            "test_maximum_complexity",
            "asyncio",
            "pytestmark",
            "TestEdgeCases",
            "test_framework_integration.py",
            "gaea2",
            "tests",
            "template-repo",
            ""
          ],
          "setup": {
            "duration": 0.0002481130068190396,
            "outcome": "passed"
          },
          "call": {
            "duration": 0.0001482520019635558,
            "outcome": "failed",
            "crash": {
              "path": "/usr/lib/python3.10/asyncio/base_events.py",
              "lineno": 584,
              "message": "RuntimeError: This event loop is already running"
            },
            "traceback": [
              {
                "path": "../../../.local/lib/python3.10/site-packages/pytest_asyncio/plugin.py",
                "lineno": 508,
                "message": "in runtest"
              },
              {
                "path": "../../../.local/lib/python3.10/site-packages/pytest_asyncio/plugin.py",
                "lineno": 773,
                "message": "in inner"
              },
              {
                "path": "/usr/lib/python3.10/asyncio/base_events.py",
                "lineno": 625,
                "message": "in run_until_complete"
              },
              {
                "path": "/usr/lib/python3.10/asyncio/base_events.py",
                "lineno": 584,
                "message": "in _check_running"
              }
            ],
            "longrepr": "../../../.local/lib/python3.10/site-packages/pytest_asyncio/plugin.py:508: in runtest\n    super().runtest()\n../../../.local/lib/python3.10/site-packages/pytest_asyncio/plugin.py:773: in inner\n    _loop.run_until_complete(task)\n/usr/lib/python3.10/asyncio/base_events.py:625: in run_until_complete\n    self._check_running()\n/usr/lib/python3.10/asyncio/base_events.py:584: in _check_running\n    raise RuntimeError('This event loop is already running')\nE   RuntimeError: This event loop is already running"
          },
          "teardown": {
            "duration": 0.00021203199867159128,
            "outcome": "passed"
          }
        },
        {
          "nodeid": "tests/gaea2/test_framework_integration.py::TestEdgeCases::test_special_characters_in_names",
          "lineno": 374,
          "outcome": "failed",
          "keywords": [
            "test_special_characters_in_names",
            "asyncio",
            "pytestmark",
            "TestEdgeCases",
            "test_framework_integration.py",
            "gaea2",
            "tests",
            "template-repo",
            ""
          ],
          "setup": {
            "duration": 0.0002518820110708475,
            "outcome": "passed"
          },
          "call": {
            "duration": 0.0001653709914535284,
            "outcome": "failed",
            "crash": {
              "path": "/usr/lib/python3.10/asyncio/base_events.py",
              "lineno": 584,
              "message": "RuntimeError: This event loop is already running"
            },
            "traceback": [
              {
                "path": "../../../.local/lib/python3.10/site-packages/pytest_asyncio/plugin.py",
                "lineno": 508,
                "message": "in runtest"
              },
              {
                "path": "../../../.local/lib/python3.10/site-packages/pytest_asyncio/plugin.py",
                "lineno": 773,
                "message": "in inner"
              },
              {
                "path": "/usr/lib/python3.10/asyncio/base_events.py",
                "lineno": 625,
                "message": "in run_until_complete"
              },
              {
                "path": "/usr/lib/python3.10/asyncio/base_events.py",
                "lineno": 584,
                "message": "in _check_running"
              }
            ],
            "longrepr": "../../../.local/lib/python3.10/site-packages/pytest_asyncio/plugin.py:508: in runtest\n    super().runtest()\n../../../.local/lib/python3.10/site-packages/pytest_asyncio/plugin.py:773: in inner\n    _loop.run_until_complete(task)\n/usr/lib/python3.10/asyncio/base_events.py:625: in run_until_complete\n    self._check_running()\n/usr/lib/python3.10/asyncio/base_events.py:584: in _check_running\n    raise RuntimeError('This event loop is already running')\nE   RuntimeError: This event loop is already running"
          },
          "teardown": {
            "duration": 0.00026951200561597943,
            "outcome": "passed"
          }
        },
        {
          "nodeid": "tests/gaea2/test_framework_integration.py::TestErrorHandling::test_malformed_json_handling",
          "lineno": 407,
          "outcome": "failed",
          "keywords": [
            "test_malformed_json_handling",
            "asyncio",
            "pytestmark",
            "TestErrorHandling",
            "test_framework_integration.py",
            "gaea2",
            "tests",
            "template-repo",
            ""
          ],
          "setup": {
            "duration": 0.0003889540093950927,
            "outcome": "passed"
          },
          "call": {
            "duration": 0.00017256202409043908,
            "outcome": "failed",
            "crash": {
              "path": "/usr/lib/python3.10/asyncio/base_events.py",
              "lineno": 584,
              "message": "RuntimeError: This event loop is already running"
            },
            "traceback": [
              {
                "path": "../../../.local/lib/python3.10/site-packages/pytest_asyncio/plugin.py",
                "lineno": 508,
                "message": "in runtest"
              },
              {
                "path": "../../../.local/lib/python3.10/site-packages/pytest_asyncio/plugin.py",
                "lineno": 773,
                "message": "in inner"
              },
              {
                "path": "/usr/lib/python3.10/asyncio/base_events.py",
                "lineno": 625,
                "message": "in run_until_complete"
              },
              {
                "path": "/usr/lib/python3.10/asyncio/base_events.py",
                "lineno": 584,
                "message": "in _check_running"
              }
            ],
            "longrepr": "../../../.local/lib/python3.10/site-packages/pytest_asyncio/plugin.py:508: in runtest\n    super().runtest()\n../../../.local/lib/python3.10/site-packages/pytest_asyncio/plugin.py:773: in inner\n    _loop.run_until_complete(task)\n/usr/lib/python3.10/asyncio/base_events.py:625: in run_until_complete\n    self._check_running()\n/usr/lib/python3.10/asyncio/base_events.py:584: in _check_running\n    raise RuntimeError('This event loop is already running')\nE   RuntimeError: This event loop is already running"
          },
          "teardown": {
            "duration": 0.000250571989454329,
            "outcome": "passed"
          }
        },
        {
          "nodeid": "tests/gaea2/test_framework_integration.py::TestErrorHandling::test_connection_recovery",
          "lineno": 418,
          "outcome": "failed",
          "keywords": [
            "test_connection_recovery",
            "asyncio",
            "pytestmark",
            "TestErrorHandling",
            "test_framework_integration.py",
            "gaea2",
            "tests",
            "template-repo",
            ""
          ],
          "setup": {
            "duration": 0.0003457639832049608,
            "outcome": "passed"
          },
          "call": {
            "duration": 0.00017567200120538473,
            "outcome": "failed",
            "crash": {
              "path": "/usr/lib/python3.10/asyncio/base_events.py",
              "lineno": 584,
              "message": "RuntimeError: This event loop is already running"
            },
            "traceback": [
              {
                "path": "../../../.local/lib/python3.10/site-packages/pytest_asyncio/plugin.py",
                "lineno": 508,
                "message": "in runtest"
              },
              {
                "path": "../../../.local/lib/python3.10/site-packages/pytest_asyncio/plugin.py",
                "lineno": 773,
                "message": "in inner"
              },
              {
                "path": "/usr/lib/python3.10/asyncio/base_events.py",
                "lineno": 625,
                "message": "in run_until_complete"
              },
              {
                "path": "/usr/lib/python3.10/asyncio/base_events.py",
                "lineno": 584,
                "message": "in _check_running"
              }
            ],
            "longrepr": "../../../.local/lib/python3.10/site-packages/pytest_asyncio/plugin.py:508: in runtest\n    super().runtest()\n../../../.local/lib/python3.10/site-packages/pytest_asyncio/plugin.py:773: in inner\n    _loop.run_until_complete(task)\n/usr/lib/python3.10/asyncio/base_events.py:625: in run_until_complete\n    self._check_running()\n/usr/lib/python3.10/asyncio/base_events.py:584: in _check_running\n    raise RuntimeError('This event loop is already running')\nE   RuntimeError: This event loop is already running"
          },
          "teardown": {
            "duration": 0.00021503301104530692,
            "outcome": "passed"
          }
        },
        {
          "nodeid": "tests/gaea2/test_framework_integration.py::TestErrorHandling::test_timeout_handling",
          "lineno": 437,
          "outcome": "failed",
          "keywords": [
            "test_timeout_handling",
            "asyncio",
            "pytestmark",
            "TestErrorHandling",
            "test_framework_integration.py",
            "gaea2",
            "tests",
            "template-repo",
            ""
          ],
          "setup": {
            "duration": 0.0002522330032661557,
            "outcome": "passed"
          },
          "call": {
            "duration": 0.00014599197311326861,
            "outcome": "failed",
            "crash": {
              "path": "/usr/lib/python3.10/asyncio/base_events.py",
              "lineno": 584,
              "message": "RuntimeError: This event loop is already running"
            },
            "traceback": [
              {
                "path": "../../../.local/lib/python3.10/site-packages/pytest_asyncio/plugin.py",
                "lineno": 508,
                "message": "in runtest"
              },
              {
                "path": "../../../.local/lib/python3.10/site-packages/pytest_asyncio/plugin.py",
                "lineno": 773,
                "message": "in inner"
              },
              {
                "path": "/usr/lib/python3.10/asyncio/base_events.py",
                "lineno": 625,
                "message": "in run_until_complete"
              },
              {
                "path": "/usr/lib/python3.10/asyncio/base_events.py",
                "lineno": 584,
                "message": "in _check_running"
              }
            ],
            "longrepr": "../../../.local/lib/python3.10/site-packages/pytest_asyncio/plugin.py:508: in runtest\n    super().runtest()\n../../../.local/lib/python3.10/site-packages/pytest_asyncio/plugin.py:773: in inner\n    _loop.run_until_complete(task)\n/usr/lib/python3.10/asyncio/base_events.py:625: in run_until_complete\n    self._check_running()\n/usr/lib/python3.10/asyncio/base_events.py:584: in _check_running\n    raise RuntimeError('This event loop is already running')\nE   RuntimeError: This event loop is already running"
          },
          "teardown": {
            "duration": 0.00023211294319480658,
            "outcome": "passed"
          }
        },
        {
          "nodeid": "tests/gaea2/test_framework_integration.py::TestRegressionSuite::test_template_consistency",
          "lineno": 468,
          "outcome": "failed",
          "keywords": [
            "test_template_consistency",
            "asyncio",
            "pytestmark",
            "TestRegressionSuite",
            "test_framework_integration.py",
            "gaea2",
            "tests",
            "template-repo",
            ""
          ],
          "setup": {
            "duration": 0.00028053298592567444,
            "outcome": "passed"
          },
          "call": {
            "duration": 0.00015102099860087037,
            "outcome": "failed",
            "crash": {
              "path": "/usr/lib/python3.10/asyncio/base_events.py",
              "lineno": 584,
              "message": "RuntimeError: This event loop is already running"
            },
            "traceback": [
              {
                "path": "../../../.local/lib/python3.10/site-packages/pytest_asyncio/plugin.py",
                "lineno": 508,
                "message": "in runtest"
              },
              {
                "path": "../../../.local/lib/python3.10/site-packages/pytest_asyncio/plugin.py",
                "lineno": 773,
                "message": "in inner"
              },
              {
                "path": "/usr/lib/python3.10/asyncio/base_events.py",
                "lineno": 625,
                "message": "in run_until_complete"
              },
              {
                "path": "/usr/lib/python3.10/asyncio/base_events.py",
                "lineno": 584,
                "message": "in _check_running"
              }
            ],
            "longrepr": "../../../.local/lib/python3.10/site-packages/pytest_asyncio/plugin.py:508: in runtest\n    super().runtest()\n../../../.local/lib/python3.10/site-packages/pytest_asyncio/plugin.py:773: in inner\n    _loop.run_until_complete(task)\n/usr/lib/python3.10/asyncio/base_events.py:625: in run_until_complete\n    self._check_running()\n/usr/lib/python3.10/asyncio/base_events.py:584: in _check_running\n    raise RuntimeError('This event loop is already running')\nE   RuntimeError: This event loop is already running"
          },
          "teardown": {
            "duration": 0.00023289199452847242,
            "outcome": "passed"
          }
        },
        {
          "nodeid": "tests/gaea2/test_framework_integration.py::TestRegressionSuite::test_validation_consistency",
          "lineno": 497,
          "outcome": "failed",
          "keywords": [
            "test_validation_consistency",
            "asyncio",
            "pytestmark",
            "TestRegressionSuite",
            "test_framework_integration.py",
            "gaea2",
            "tests",
            "template-repo",
            ""
          ],
          "setup": {
            "duration": 0.0002957729739136994,
            "outcome": "passed"
          },
          "call": {
            "duration": 0.0001716320402920246,
            "outcome": "failed",
            "crash": {
              "path": "/usr/lib/python3.10/asyncio/base_events.py",
              "lineno": 584,
              "message": "RuntimeError: This event loop is already running"
            },
            "traceback": [
              {
                "path": "../../../.local/lib/python3.10/site-packages/pytest_asyncio/plugin.py",
                "lineno": 508,
                "message": "in runtest"
              },
              {
                "path": "../../../.local/lib/python3.10/site-packages/pytest_asyncio/plugin.py",
                "lineno": 773,
                "message": "in inner"
              },
              {
                "path": "/usr/lib/python3.10/asyncio/base_events.py",
                "lineno": 625,
                "message": "in run_until_complete"
              },
              {
                "path": "/usr/lib/python3.10/asyncio/base_events.py",
                "lineno": 584,
                "message": "in _check_running"
              }
            ],
            "longrepr": "../../../.local/lib/python3.10/site-packages/pytest_asyncio/plugin.py:508: in runtest\n    super().runtest()\n../../../.local/lib/python3.10/site-packages/pytest_asyncio/plugin.py:773: in inner\n    _loop.run_until_complete(task)\n/usr/lib/python3.10/asyncio/base_events.py:625: in run_until_complete\n    self._check_running()\n/usr/lib/python3.10/asyncio/base_events.py:584: in _check_running\n    raise RuntimeError('This event loop is already running')\nE   RuntimeError: This event loop is already running"
          },
          "teardown": {
            "duration": 0.0004268450429663062,
            "outcome": "passed"
          }
        }
      ]
    },
    "operations": {
      "exit_code": 1,
      "total": 13,
      "passed": 0,
      "failed": 13,
      "skipped": 0,
      "duration": 0.4061875343322754,
      "tests": [
        {
          "nodeid": "tests/gaea2/test_gaea_operations.py::TestGaea2Operations::test_common_workflow_pattern",
          "lineno": 28,
          "outcome": "failed",
          "keywords": [
            "test_common_workflow_pattern",
            "asyncio",
            "pytestmark",
            "TestGaea2Operations",
            "test_gaea_operations.py",
            "gaea2",
            "tests",
            "template-repo",
            ""
          ],
          "setup": {
            "duration": 0.00043130398262292147,
            "outcome": "passed"
          },
          "call": {
            "duration": 0.00022348196944221854,
            "outcome": "failed",
            "crash": {
              "path": "/usr/lib/python3.10/asyncio/base_events.py",
              "lineno": 584,
              "message": "RuntimeError: This event loop is already running"
            },
            "traceback": [
              {
                "path": "../../../.local/lib/python3.10/site-packages/pytest_asyncio/plugin.py",
                "lineno": 508,
                "message": "in runtest"
              },
              {
                "path": "../../../.local/lib/python3.10/site-packages/pytest_asyncio/plugin.py",
                "lineno": 773,
                "message": "in inner"
              },
              {
                "path": "/usr/lib/python3.10/asyncio/base_events.py",
                "lineno": 625,
                "message": "in run_until_complete"
              },
              {
                "path": "/usr/lib/python3.10/asyncio/base_events.py",
                "lineno": 584,
                "message": "in _check_running"
              }
            ],
            "longrepr": "../../../.local/lib/python3.10/site-packages/pytest_asyncio/plugin.py:508: in runtest\n    super().runtest()\n../../../.local/lib/python3.10/site-packages/pytest_asyncio/plugin.py:773: in inner\n    _loop.run_until_complete(task)\n/usr/lib/python3.10/asyncio/base_events.py:625: in run_until_complete\n    self._check_running()\n/usr/lib/python3.10/asyncio/base_events.py:584: in _check_running\n    raise RuntimeError('This event loop is already running')\nE   RuntimeError: This event loop is already running"
          },
          "teardown": {
            "duration": 0.00026909203734248877,
            "outcome": "passed"
          }
        },
        {
          "nodeid": "tests/gaea2/test_gaea_operations.py::TestGaea2Operations::test_multi_output_nodes",
          "lineno": 117,
          "outcome": "failed",
          "keywords": [
            "test_multi_output_nodes",
            "asyncio",
            "pytestmark",
            "TestGaea2Operations",
            "test_gaea_operations.py",
            "gaea2",
            "tests",
            "template-repo",
            ""
          ],
          "setup": {
            "duration": 0.00024797202786430717,
            "outcome": "passed"
          },
          "call": {
            "duration": 0.00015636096941307187,
            "outcome": "failed",
            "crash": {
              "path": "/usr/lib/python3.10/asyncio/base_events.py",
              "lineno": 584,
              "message": "RuntimeError: This event loop is already running"
            },
            "traceback": [
              {
                "path": "../../../.local/lib/python3.10/site-packages/pytest_asyncio/plugin.py",
                "lineno": 508,
                "message": "in runtest"
              },
              {
                "path": "../../../.local/lib/python3.10/site-packages/pytest_asyncio/plugin.py",
                "lineno": 773,
                "message": "in inner"
              },
              {
                "path": "/usr/lib/python3.10/asyncio/base_events.py",
                "lineno": 625,
                "message": "in run_until_complete"
              },
              {
                "path": "/usr/lib/python3.10/asyncio/base_events.py",
                "lineno": 584,
                "message": "in _check_running"
              }
            ],
            "longrepr": "../../../.local/lib/python3.10/site-packages/pytest_asyncio/plugin.py:508: in runtest\n    super().runtest()\n../../../.local/lib/python3.10/site-packages/pytest_asyncio/plugin.py:773: in inner\n    _loop.run_until_complete(task)\n/usr/lib/python3.10/asyncio/base_events.py:625: in run_until_complete\n    self._check_running()\n/usr/lib/python3.10/asyncio/base_events.py:584: in _check_running\n    raise RuntimeError('This event loop is already running')\nE   RuntimeError: This event loop is already running"
          },
          "teardown": {
            "duration": 0.00019005202921107411,
            "outcome": "passed"
          }
        },
        {
          "nodeid": "tests/gaea2/test_gaea_operations.py::TestGaea2Operations::test_complex_property_nodes",
          "lineno": 177,
          "outcome": "failed",
          "keywords": [
            "test_complex_property_nodes",
            "asyncio",
            "pytestmark",
            "TestGaea2Operations",
            "test_gaea_operations.py",
            "gaea2",
            "tests",
            "template-repo",
            ""
          ],
          "setup": {
            "duration": 0.00025699299294501543,
            "outcome": "passed"
          },
          "call": {
            "duration": 0.0001400710316374898,
            "outcome": "failed",
            "crash": {
              "path": "/usr/lib/python3.10/asyncio/base_events.py",
              "lineno": 584,
              "message": "RuntimeError: This event loop is already running"
            },
            "traceback": [
              {
                "path": "../../../.local/lib/python3.10/site-packages/pytest_asyncio/plugin.py",
                "lineno": 508,
                "message": "in runtest"
              },
              {
                "path": "../../../.local/lib/python3.10/site-packages/pytest_asyncio/plugin.py",
                "lineno": 773,
                "message": "in inner"
              },
              {
                "path": "/usr/lib/python3.10/asyncio/base_events.py",
                "lineno": 625,
                "message": "in run_until_complete"
              },
              {
                "path": "/usr/lib/python3.10/asyncio/base_events.py",
                "lineno": 584,
                "message": "in _check_running"
              }
            ],
            "longrepr": "../../../.local/lib/python3.10/site-packages/pytest_asyncio/plugin.py:508: in runtest\n    super().runtest()\n../../../.local/lib/python3.10/site-packages/pytest_asyncio/plugin.py:773: in inner\n    _loop.run_until_complete(task)\n/usr/lib/python3.10/asyncio/base_events.py:625: in run_until_complete\n    self._check_running()\n/usr/lib/python3.10/asyncio/base_events.py:584: in _check_running\n    raise RuntimeError('This event loop is already running')\nE   RuntimeError: This event loop is already running"
          },
          "teardown": {
            "duration": 0.0001930519938468933,
            "outcome": "passed"
          }
        },
        {
          "nodeid": "tests/gaea2/test_gaea_operations.py::TestGaea2Operations::test_template_variations",
          "lineno": 222,
          "outcome": "failed",
          "keywords": [
            "test_template_variations",
            "asyncio",
            "pytestmark",
            "TestGaea2Operations",
            "test_gaea_operations.py",
            "gaea2",
            "tests",
            "template-repo",
            ""
          ],
          "setup": {
            "duration": 0.00024753203615546227,
            "outcome": "passed"
          },
          "call": {
            "duration": 0.0001437310129404068,
            "outcome": "failed",
            "crash": {
              "path": "/usr/lib/python3.10/asyncio/base_events.py",
              "lineno": 584,
              "message": "RuntimeError: This event loop is already running"
            },
            "traceback": [
              {
                "path": "../../../.local/lib/python3.10/site-packages/pytest_asyncio/plugin.py",
                "lineno": 508,
                "message": "in runtest"
              },
              {
                "path": "../../../.local/lib/python3.10/site-packages/pytest_asyncio/plugin.py",
                "lineno": 773,
                "message": "in inner"
              },
              {
                "path": "/usr/lib/python3.10/asyncio/base_events.py",
                "lineno": 625,
                "message": "in run_until_complete"
              },
              {
                "path": "/usr/lib/python3.10/asyncio/base_events.py",
                "lineno": 584,
                "message": "in _check_running"
              }
            ],
            "longrepr": "../../../.local/lib/python3.10/site-packages/pytest_asyncio/plugin.py:508: in runtest\n    super().runtest()\n../../../.local/lib/python3.10/site-packages/pytest_asyncio/plugin.py:773: in inner\n    _loop.run_until_complete(task)\n/usr/lib/python3.10/asyncio/base_events.py:625: in run_until_complete\n    self._check_running()\n/usr/lib/python3.10/asyncio/base_events.py:584: in _check_running\n    raise RuntimeError('This event loop is already running')\nE   RuntimeError: This event loop is already running"
          },
          "teardown": {
            "duration": 0.00027388299349695444,
            "outcome": "passed"
          }
        },
        {
          "nodeid": "tests/gaea2/test_gaea_operations.py::TestGaea2Operations::test_combine_node_connections",
          "lineno": 258,
          "outcome": "failed",
          "keywords": [
            "test_combine_node_connections",
            "asyncio",
            "pytestmark",
            "TestGaea2Operations",
            "test_gaea_operations.py",
            "gaea2",
            "tests",
            "template-repo",
            ""
          ],
          "setup": {
            "duration": 0.00025803298922255635,
            "outcome": "passed"
          },
          "call": {
            "duration": 0.00016963103553280234,
            "outcome": "failed",
            "crash": {
              "path": "/usr/lib/python3.10/asyncio/base_events.py",
              "lineno": 584,
              "message": "RuntimeError: This event loop is already running"
            },
            "traceback": [
              {
                "path": "../../../.local/lib/python3.10/site-packages/pytest_asyncio/plugin.py",
                "lineno": 508,
                "message": "in runtest"
              },
              {
                "path": "../../../.local/lib/python3.10/site-packages/pytest_asyncio/plugin.py",
                "lineno": 773,
                "message": "in inner"
              },
              {
                "path": "/usr/lib/python3.10/asyncio/base_events.py",
                "lineno": 625,
                "message": "in run_until_complete"
              },
              {
                "path": "/usr/lib/python3.10/asyncio/base_events.py",
                "lineno": 584,
                "message": "in _check_running"
              }
            ],
            "longrepr": "../../../.local/lib/python3.10/site-packages/pytest_asyncio/plugin.py:508: in runtest\n    super().runtest()\n../../../.local/lib/python3.10/site-packages/pytest_asyncio/plugin.py:773: in inner\n    _loop.run_until_complete(task)\n/usr/lib/python3.10/asyncio/base_events.py:625: in run_until_complete\n    self._check_running()\n/usr/lib/python3.10/asyncio/base_events.py:584: in _check_running\n    raise RuntimeError('This event loop is already running')\nE   RuntimeError: This event loop is already running"
          },
          "teardown": {
            "duration": 0.0003103639464825392,
            "outcome": "passed"
          }
        },
        {
          "nodeid": "tests/gaea2/test_gaea_operations.py::TestGaea2Operations::test_workflow_optimization",
          "lineno": 294,
          "outcome": "failed",
          "keywords": [
            "test_workflow_optimization",
            "asyncio",
            "pytestmark",
            "TestGaea2Operations",
            "test_gaea_operations.py",
            "gaea2",
            "tests",
            "template-repo",
            ""
          ],
          "setup": {
            "duration": 0.00032915297197178006,
            "outcome": "passed"
          },
          "call": {
            "duration": 0.00016580196097493172,
            "outcome": "failed",
            "crash": {
              "path": "/usr/lib/python3.10/asyncio/base_events.py",
              "lineno": 584,
              "message": "RuntimeError: This event loop is already running"
            },
            "traceback": [
              {
                "path": "../../../.local/lib/python3.10/site-packages/pytest_asyncio/plugin.py",
                "lineno": 508,
                "message": "in runtest"
              },
              {
                "path": "../../../.local/lib/python3.10/site-packages/pytest_asyncio/plugin.py",
                "lineno": 773,
                "message": "in inner"
              },
              {
                "path": "/usr/lib/python3.10/asyncio/base_events.py",
                "lineno": 625,
                "message": "in run_until_complete"
              },
              {
                "path": "/usr/lib/python3.10/asyncio/base_events.py",
                "lineno": 584,
                "message": "in _check_running"
              }
            ],
            "longrepr": "../../../.local/lib/python3.10/site-packages/pytest_asyncio/plugin.py:508: in runtest\n    super().runtest()\n../../../.local/lib/python3.10/site-packages/pytest_asyncio/plugin.py:773: in inner\n    _loop.run_until_complete(task)\n/usr/lib/python3.10/asyncio/base_events.py:625: in run_until_complete\n    self._check_running()\n/usr/lib/python3.10/asyncio/base_events.py:584: in _check_running\n    raise RuntimeError('This event loop is already running')\nE   RuntimeError: This event loop is already running"
          },
          "teardown": {
            "duration": 0.00023211201187223196,
            "outcome": "passed"
          }
        },
        {
          "nodeid": "tests/gaea2/test_gaea_operations.py::TestGaea2Operations::test_node_suggestions_context",
          "lineno": 370,
          "outcome": "failed",
          "keywords": [
            "test_node_suggestions_context",
            "asyncio",
            "pytestmark",
            "TestGaea2Operations",
            "test_gaea_operations.py",
            "gaea2",
            "tests",
            "template-repo",
            ""
          ],
          "setup": {
            "duration": 0.00028631300665438175,
            "outcome": "passed"
          },
          "call": {
            "duration": 0.00021234300220385194,
            "outcome": "failed",
            "crash": {
              "path": "/usr/lib/python3.10/asyncio/base_events.py",
              "lineno": 584,
              "message": "RuntimeError: This event loop is already running"
            },
            "traceback": [
              {
                "path": "../../../.local/lib/python3.10/site-packages/pytest_asyncio/plugin.py",
                "lineno": 508,
                "message": "in runtest"
              },
              {
                "path": "../../../.local/lib/python3.10/site-packages/pytest_asyncio/plugin.py",
                "lineno": 773,
                "message": "in inner"
              },
              {
                "path": "/usr/lib/python3.10/asyncio/base_events.py",
                "lineno": 625,
                "message": "in run_until_complete"
              },
              {
                "path": "/usr/lib/python3.10/asyncio/base_events.py",
                "lineno": 584,
                "message": "in _check_running"
              }
            ],
            "longrepr": "../../../.local/lib/python3.10/site-packages/pytest_asyncio/plugin.py:508: in runtest\n    super().runtest()\n../../../.local/lib/python3.10/site-packages/pytest_asyncio/plugin.py:773: in inner\n    _loop.run_until_complete(task)\n/usr/lib/python3.10/asyncio/base_events.py:625: in run_until_complete\n    self._check_running()\n/usr/lib/python3.10/asyncio/base_events.py:584: in _check_running\n    raise RuntimeError('This event loop is already running')\nE   RuntimeError: This event loop is already running"
          },
          "teardown": {
            "duration": 0.00025399302830919623,
            "outcome": "passed"
          }
        },
        {
          "nodeid": "tests/gaea2/test_gaea_operations.py::TestGaea2Operations::test_workflow_repair",
          "lineno": 456,
          "outcome": "failed",
          "keywords": [
            "test_workflow_repair",
            "asyncio",
            "pytestmark",
            "TestGaea2Operations",
            "test_gaea_operations.py",
            "gaea2",
            "tests",
            "template-repo",
            ""
          ],
          "setup": {
            "duration": 0.00028339296113699675,
            "outcome": "passed"
          },
          "call": {
            "duration": 0.00019591196905821562,
            "outcome": "failed",
            "crash": {
              "path": "/usr/lib/python3.10/asyncio/base_events.py",
              "lineno": 584,
              "message": "RuntimeError: This event loop is already running"
            },
            "traceback": [
              {
                "path": "../../../.local/lib/python3.10/site-packages/pytest_asyncio/plugin.py",
                "lineno": 508,
                "message": "in runtest"
              },
              {
                "path": "../../../.local/lib/python3.10/site-packages/pytest_asyncio/plugin.py",
                "lineno": 773,
                "message": "in inner"
              },
              {
                "path": "/usr/lib/python3.10/asyncio/base_events.py",
                "lineno": 625,
                "message": "in run_until_complete"
              },
              {
                "path": "/usr/lib/python3.10/asyncio/base_events.py",
                "lineno": 584,
                "message": "in _check_running"
              }
            ],
            "longrepr": "../../../.local/lib/python3.10/site-packages/pytest_asyncio/plugin.py:508: in runtest\n    super().runtest()\n../../../.local/lib/python3.10/site-packages/pytest_asyncio/plugin.py:773: in inner\n    _loop.run_until_complete(task)\n/usr/lib/python3.10/asyncio/base_events.py:625: in run_until_complete\n    self._check_running()\n/usr/lib/python3.10/asyncio/base_events.py:584: in _check_running\n    raise RuntimeError('This event loop is already running')\nE   RuntimeError: This event loop is already running"
          },
          "teardown": {
            "duration": 0.0002544830203987658,
            "outcome": "passed"
          }
        },
        {
          "nodeid": "tests/gaea2/test_gaea_operations.py::TestGaea2Operations::test_pattern_analysis",
          "lineno": 538,
          "outcome": "failed",
          "keywords": [
            "test_pattern_analysis",
            "asyncio",
            "pytestmark",
            "TestGaea2Operations",
            "test_gaea_operations.py",
            "gaea2",
            "tests",
            "template-repo",
            ""
          ],
          "setup": {
            "duration": 0.00031385303009301424,
            "outcome": "passed"
          },
          "call": {
            "duration": 0.0002637729630805552,
            "outcome": "failed",
            "crash": {
              "path": "/usr/lib/python3.10/asyncio/base_events.py",
              "lineno": 584,
              "message": "RuntimeError: This event loop is already running"
            },
            "traceback": [
              {
                "path": "../../../.local/lib/python3.10/site-packages/pytest_asyncio/plugin.py",
                "lineno": 508,
                "message": "in runtest"
              },
              {
                "path": "../../../.local/lib/python3.10/site-packages/pytest_asyncio/plugin.py",
                "lineno": 773,
                "message": "in inner"
              },
              {
                "path": "/usr/lib/python3.10/asyncio/base_events.py",
                "lineno": 625,
                "message": "in run_until_complete"
              },
              {
                "path": "/usr/lib/python3.10/asyncio/base_events.py",
                "lineno": 584,
                "message": "in _check_running"
              }
            ],
            "longrepr": "../../../.local/lib/python3.10/site-packages/pytest_asyncio/plugin.py:508: in runtest\n    super().runtest()\n../../../.local/lib/python3.10/site-packages/pytest_asyncio/plugin.py:773: in inner\n    _loop.run_until_complete(task)\n/usr/lib/python3.10/asyncio/base_events.py:625: in run_until_complete\n    self._check_running()\n/usr/lib/python3.10/asyncio/base_events.py:584: in _check_running\n    raise RuntimeError('This event loop is already running')\nE   RuntimeError: This event loop is already running"
          },
          "teardown": {
            "duration": 0.000291112984996289,
            "outcome": "passed"
          }
        },
        {
          "nodeid": "tests/gaea2/test_gaea_operations.py::TestGaea2Operations::test_variable_propagation",
          "lineno": 576,
          "outcome": "failed",
          "keywords": [
            "test_variable_propagation",
            "asyncio",
            "pytestmark",
            "TestGaea2Operations",
            "test_gaea_operations.py",
            "gaea2",
            "tests",
            "template-repo",
            ""
          ],
          "setup": {
            "duration": 0.00029748299857601523,
            "outcome": "passed"
          },
          "call": {
            "duration": 0.00015998200979083776,
            "outcome": "failed",
            "crash": {
              "path": "/usr/lib/python3.10/asyncio/base_events.py",
              "lineno": 584,
              "message": "RuntimeError: This event loop is already running"
            },
            "traceback": [
              {
                "path": "../../../.local/lib/python3.10/site-packages/pytest_asyncio/plugin.py",
                "lineno": 508,
                "message": "in runtest"
              },
              {
                "path": "../../../.local/lib/python3.10/site-packages/pytest_asyncio/plugin.py",
                "lineno": 773,
                "message": "in inner"
              },
              {
                "path": "/usr/lib/python3.10/asyncio/base_events.py",
                "lineno": 625,
                "message": "in run_until_complete"
              },
              {
                "path": "/usr/lib/python3.10/asyncio/base_events.py",
                "lineno": 584,
                "message": "in _check_running"
              }
            ],
            "longrepr": "../../../.local/lib/python3.10/site-packages/pytest_asyncio/plugin.py:508: in runtest\n    super().runtest()\n../../../.local/lib/python3.10/site-packages/pytest_asyncio/plugin.py:773: in inner\n    _loop.run_until_complete(task)\n/usr/lib/python3.10/asyncio/base_events.py:625: in run_until_complete\n    self._check_running()\n/usr/lib/python3.10/asyncio/base_events.py:584: in _check_running\n    raise RuntimeError('This event loop is already running')\nE   RuntimeError: This event loop is already running"
          },
          "teardown": {
            "duration": 0.00036691402783617377,
            "outcome": "passed"
          }
        },
        {
          "nodeid": "tests/gaea2/test_gaea_operations.py::TestEdgeCasesAndBoundaries::test_maximum_node_limit",
          "lineno": 639,
          "outcome": "failed",
          "keywords": [
            "test_maximum_node_limit",
            "asyncio",
            "pytestmark",
            "TestEdgeCasesAndBoundaries",
            "test_gaea_operations.py",
            "gaea2",
            "tests",
            "template-repo",
            ""
          ],
          "setup": {
            "duration": 0.00032082299003377557,
            "outcome": "passed"
          },
          "call": {
            "duration": 0.00024939299328252673,
            "outcome": "failed",
            "crash": {
              "path": "/usr/lib/python3.10/asyncio/base_events.py",
              "lineno": 584,
              "message": "RuntimeError: This event loop is already running"
            },
            "traceback": [
              {
                "path": "../../../.local/lib/python3.10/site-packages/pytest_asyncio/plugin.py",
                "lineno": 508,
                "message": "in runtest"
              },
              {
                "path": "../../../.local/lib/python3.10/site-packages/pytest_asyncio/plugin.py",
                "lineno": 773,
                "message": "in inner"
              },
              {
                "path": "/usr/lib/python3.10/asyncio/base_events.py",
                "lineno": 625,
                "message": "in run_until_complete"
              },
              {
                "path": "/usr/lib/python3.10/asyncio/base_events.py",
                "lineno": 584,
                "message": "in _check_running"
              }
            ],
            "longrepr": "../../../.local/lib/python3.10/site-packages/pytest_asyncio/plugin.py:508: in runtest\n    super().runtest()\n../../../.local/lib/python3.10/site-packages/pytest_asyncio/plugin.py:773: in inner\n    _loop.run_until_complete(task)\n/usr/lib/python3.10/asyncio/base_events.py:625: in run_until_complete\n    self._check_running()\n/usr/lib/python3.10/asyncio/base_events.py:584: in _check_running\n    raise RuntimeError('This event loop is already running')\nE   RuntimeError: This event loop is already running"
          },
          "teardown": {
            "duration": 0.00027563300682231784,
            "outcome": "passed"
          }
        },
        {
          "nodeid": "tests/gaea2/test_gaea_operations.py::TestEdgeCasesAndBoundaries::test_deeply_nested_combines",
          "lineno": 686,
          "outcome": "failed",
          "keywords": [
            "test_deeply_nested_combines",
            "asyncio",
            "pytestmark",
            "TestEdgeCasesAndBoundaries",
            "test_gaea_operations.py",
            "gaea2",
            "tests",
            "template-repo",
            ""
          ],
          "setup": {
            "duration": 0.00027236301684752107,
            "outcome": "passed"
          },
          "call": {
            "duration": 0.00016289204359054565,
            "outcome": "failed",
            "crash": {
              "path": "/usr/lib/python3.10/asyncio/base_events.py",
              "lineno": 584,
              "message": "RuntimeError: This event loop is already running"
            },
            "traceback": [
              {
                "path": "../../../.local/lib/python3.10/site-packages/pytest_asyncio/plugin.py",
                "lineno": 508,
                "message": "in runtest"
              },
              {
                "path": "../../../.local/lib/python3.10/site-packages/pytest_asyncio/plugin.py",
                "lineno": 773,
                "message": "in inner"
              },
              {
                "path": "/usr/lib/python3.10/asyncio/base_events.py",
                "lineno": 625,
                "message": "in run_until_complete"
              },
              {
                "path": "/usr/lib/python3.10/asyncio/base_events.py",
                "lineno": 584,
                "message": "in _check_running"
              }
            ],
            "longrepr": "../../../.local/lib/python3.10/site-packages/pytest_asyncio/plugin.py:508: in runtest\n    super().runtest()\n../../../.local/lib/python3.10/site-packages/pytest_asyncio/plugin.py:773: in inner\n    _loop.run_until_complete(task)\n/usr/lib/python3.10/asyncio/base_events.py:625: in run_until_complete\n    self._check_running()\n/usr/lib/python3.10/asyncio/base_events.py:584: in _check_running\n    raise RuntimeError('This event loop is already running')\nE   RuntimeError: This event loop is already running"
          },
          "teardown": {
            "duration": 0.0002272329875268042,
            "outcome": "passed"
          }
        },
        {
          "nodeid": "tests/gaea2/test_gaea_operations.py::TestEdgeCasesAndBoundaries::test_special_port_connections",
          "lineno": 754,
          "outcome": "failed",
          "keywords": [
            "test_special_port_connections",
            "asyncio",
            "pytestmark",
            "TestEdgeCasesAndBoundaries",
            "test_gaea_operations.py",
            "gaea2",
            "tests",
            "template-repo",
            ""
          ],
          "setup": {
            "duration": 0.00028844299959018826,
            "outcome": "passed"
          },
          "call": {
            "duration": 0.00024204299552366138,
            "outcome": "failed",
            "crash": {
              "path": "/usr/lib/python3.10/asyncio/base_events.py",
              "lineno": 584,
              "message": "RuntimeError: This event loop is already running"
            },
            "traceback": [
              {
                "path": "../../../.local/lib/python3.10/site-packages/pytest_asyncio/plugin.py",
                "lineno": 508,
                "message": "in runtest"
              },
              {
                "path": "../../../.local/lib/python3.10/site-packages/pytest_asyncio/plugin.py",
                "lineno": 773,
                "message": "in inner"
              },
              {
                "path": "/usr/lib/python3.10/asyncio/base_events.py",
                "lineno": 625,
                "message": "in run_until_complete"
              },
              {
                "path": "/usr/lib/python3.10/asyncio/base_events.py",
                "lineno": 584,
                "message": "in _check_running"
              }
            ],
            "longrepr": "../../../.local/lib/python3.10/site-packages/pytest_asyncio/plugin.py:508: in runtest\n    super().runtest()\n../../../.local/lib/python3.10/site-packages/pytest_asyncio/plugin.py:773: in inner\n    _loop.run_until_complete(task)\n/usr/lib/python3.10/asyncio/base_events.py:625: in run_until_complete\n    self._check_running()\n/usr/lib/python3.10/asyncio/base_events.py:584: in _check_running\n    raise RuntimeError('This event loop is already running')\nE   RuntimeError: This event loop is already running"
          },
          "teardown": {
            "duration": 0.0006797069800086319,
            "outcome": "passed"
          }
        }
      ]
    },
    "failures": {
      "exit_code": 1,
      "total": 9,
      "passed": 0,
      "failed": 9,
      "skipped": 0,
      "duration": 0.2755916118621826,
      "tests": [
        {
          "nodeid": "tests/gaea2/test_gaea_failures.py::TestGaea2Failures::test_invalid_node_types",
          "lineno": 31,
          "outcome": "failed",
          "keywords": [
            "test_invalid_node_types",
            "asyncio",
            "pytestmark",
            "TestGaea2Failures",
            "test_gaea_failures.py",
            "gaea2",
            "tests",
            "template-repo",
            ""
          ],
          "setup": {
            "duration": 0.0003437139675952494,
            "outcome": "passed"
          },
          "call": {
            "duration": 0.00021924200700595975,
            "outcome": "failed",
            "crash": {
              "path": "/usr/lib/python3.10/asyncio/base_events.py",
              "lineno": 584,
              "message": "RuntimeError: This event loop is already running"
            },
            "traceback": [
              {
                "path": "../../../.local/lib/python3.10/site-packages/pytest_asyncio/plugin.py",
                "lineno": 508,
                "message": "in runtest"
              },
              {
                "path": "../../../.local/lib/python3.10/site-packages/pytest_asyncio/plugin.py",
                "lineno": 773,
                "message": "in inner"
              },
              {
                "path": "/usr/lib/python3.10/asyncio/base_events.py",
                "lineno": 625,
                "message": "in run_until_complete"
              },
              {
                "path": "/usr/lib/python3.10/asyncio/base_events.py",
                "lineno": 584,
                "message": "in _check_running"
              }
            ],
            "longrepr": "../../../.local/lib/python3.10/site-packages/pytest_asyncio/plugin.py:508: in runtest\n    super().runtest()\n../../../.local/lib/python3.10/site-packages/pytest_asyncio/plugin.py:773: in inner\n    _loop.run_until_complete(task)\n/usr/lib/python3.10/asyncio/base_events.py:625: in run_until_complete\n    self._check_running()\n/usr/lib/python3.10/asyncio/base_events.py:584: in _check_running\n    raise RuntimeError('This event loop is already running')\nE   RuntimeError: This event loop is already running"
          },
          "teardown": {
            "duration": 0.00022541196085512638,
            "outcome": "passed"
          }
        },
        {
          "nodeid": "tests/gaea2/test_gaea_failures.py::TestGaea2Failures::test_invalid_connections",
          "lineno": 124,
          "outcome": "failed",
          "keywords": [
            "test_invalid_connections",
            "asyncio",
            "pytestmark",
            "TestGaea2Failures",
            "test_gaea_failures.py",
            "gaea2",
            "tests",
            "template-repo",
            ""
          ],
          "setup": {
            "duration": 0.0002585020265541971,
            "outcome": "passed"
          },
          "call": {
            "duration": 0.0001446810201741755,
            "outcome": "failed",
            "crash": {
              "path": "/usr/lib/python3.10/asyncio/base_events.py",
              "lineno": 584,
              "message": "RuntimeError: This event loop is already running"
            },
            "traceback": [
              {
                "path": "../../../.local/lib/python3.10/site-packages/pytest_asyncio/plugin.py",
                "lineno": 508,
                "message": "in runtest"
              },
              {
                "path": "../../../.local/lib/python3.10/site-packages/pytest_asyncio/plugin.py",
                "lineno": 773,
                "message": "in inner"
              },
              {
                "path": "/usr/lib/python3.10/asyncio/base_events.py",
                "lineno": 625,
                "message": "in run_until_complete"
              },
              {
                "path": "/usr/lib/python3.10/asyncio/base_events.py",
                "lineno": 584,
                "message": "in _check_running"
              }
            ],
            "longrepr": "../../../.local/lib/python3.10/site-packages/pytest_asyncio/plugin.py:508: in runtest\n    super().runtest()\n../../../.local/lib/python3.10/site-packages/pytest_asyncio/plugin.py:773: in inner\n    _loop.run_until_complete(task)\n/usr/lib/python3.10/asyncio/base_events.py:625: in run_until_complete\n    self._check_running()\n/usr/lib/python3.10/asyncio/base_events.py:584: in _check_running\n    raise RuntimeError('This event loop is already running')\nE   RuntimeError: This event loop is already running"
          },
          "teardown": {
            "duration": 0.0003374940133653581,
            "outcome": "passed"
          }
        },
        {
          "nodeid": "tests/gaea2/test_gaea_failures.py::TestGaea2Failures::test_missing_required_nodes",
          "lineno": 228,
          "outcome": "failed",
          "keywords": [
            "test_missing_required_nodes",
            "asyncio",
            "pytestmark",
            "TestGaea2Failures",
            "test_gaea_failures.py",
            "gaea2",
            "tests",
            "template-repo",
            ""
          ],
          "setup": {
            "duration": 0.0003324129502288997,
            "outcome": "passed"
          },
          "call": {
            "duration": 0.000196542008779943,
            "outcome": "failed",
            "crash": {
              "path": "/usr/lib/python3.10/asyncio/base_events.py",
              "lineno": 584,
              "message": "RuntimeError: This event loop is already running"
            },
            "traceback": [
              {
                "path": "../../../.local/lib/python3.10/site-packages/pytest_asyncio/plugin.py",
                "lineno": 508,
                "message": "in runtest"
              },
              {
                "path": "../../../.local/lib/python3.10/site-packages/pytest_asyncio/plugin.py",
                "lineno": 773,
                "message": "in inner"
              },
              {
                "path": "/usr/lib/python3.10/asyncio/base_events.py",
                "lineno": 625,
                "message": "in run_until_complete"
              },
              {
                "path": "/usr/lib/python3.10/asyncio/base_events.py",
                "lineno": 584,
                "message": "in _check_running"
              }
            ],
            "longrepr": "../../../.local/lib/python3.10/site-packages/pytest_asyncio/plugin.py:508: in runtest\n    super().runtest()\n../../../.local/lib/python3.10/site-packages/pytest_asyncio/plugin.py:773: in inner\n    _loop.run_until_complete(task)\n/usr/lib/python3.10/asyncio/base_events.py:625: in run_until_complete\n    self._check_running()\n/usr/lib/python3.10/asyncio/base_events.py:584: in _check_running\n    raise RuntimeError('This event loop is already running')\nE   RuntimeError: This event loop is already running"
          },
          "teardown": {
            "duration": 0.000204161973670125,
            "outcome": "passed"
          }
        },
        {
          "nodeid": "tests/gaea2/test_gaea_failures.py::TestGaea2Failures::test_invalid_property_values",
          "lineno": 315,
          "outcome": "failed",
          "keywords": [
            "test_invalid_property_values",
            "asyncio",
            "pytestmark",
            "TestGaea2Failures",
            "test_gaea_failures.py",
            "gaea2",
            "tests",
            "template-repo",
            ""
          ],
          "setup": {
            "duration": 0.0002627720241434872,
            "outcome": "passed"
          },
          "call": {
            "duration": 0.00015099201118573546,
            "outcome": "failed",
            "crash": {
              "path": "/usr/lib/python3.10/asyncio/base_events.py",
              "lineno": 584,
              "message": "RuntimeError: This event loop is already running"
            },
            "traceback": [
              {
                "path": "../../../.local/lib/python3.10/site-packages/pytest_asyncio/plugin.py",
                "lineno": 508,
                "message": "in runtest"
              },
              {
                "path": "../../../.local/lib/python3.10/site-packages/pytest_asyncio/plugin.py",
                "lineno": 773,
                "message": "in inner"
              },
              {
                "path": "/usr/lib/python3.10/asyncio/base_events.py",
                "lineno": 625,
                "message": "in run_until_complete"
              },
              {
                "path": "/usr/lib/python3.10/asyncio/base_events.py",
                "lineno": 584,
                "message": "in _check_running"
              }
            ],
            "longrepr": "../../../.local/lib/python3.10/site-packages/pytest_asyncio/plugin.py:508: in runtest\n    super().runtest()\n../../../.local/lib/python3.10/site-packages/pytest_asyncio/plugin.py:773: in inner\n    _loop.run_until_complete(task)\n/usr/lib/python3.10/asyncio/base_events.py:625: in run_until_complete\n    self._check_running()\n/usr/lib/python3.10/asyncio/base_events.py:584: in _check_running\n    raise RuntimeError('This event loop is already running')\nE   RuntimeError: This event loop is already running"
          },
          "teardown": {
            "duration": 0.00022543204249814153,
            "outcome": "passed"
          }
        },
        {
          "nodeid": "tests/gaea2/test_gaea_failures.py::TestGaea2Failures::test_malformed_requests",
          "lineno": 414,
          "outcome": "failed",
          "keywords": [
            "test_malformed_requests",
            "asyncio",
            "pytestmark",
            "TestGaea2Failures",
            "test_gaea_failures.py",
            "gaea2",
            "tests",
            "template-repo",
            ""
          ],
          "setup": {
            "duration": 0.000260622997302562,
            "outcome": "passed"
          },
          "call": {
            "duration": 0.00015163194620981812,
            "outcome": "failed",
            "crash": {
              "path": "/usr/lib/python3.10/asyncio/base_events.py",
              "lineno": 584,
              "message": "RuntimeError: This event loop is already running"
            },
            "traceback": [
              {
                "path": "../../../.local/lib/python3.10/site-packages/pytest_asyncio/plugin.py",
                "lineno": 508,
                "message": "in runtest"
              },
              {
                "path": "../../../.local/lib/python3.10/site-packages/pytest_asyncio/plugin.py",
                "lineno": 773,
                "message": "in inner"
              },
              {
                "path": "/usr/lib/python3.10/asyncio/base_events.py",
                "lineno": 625,
                "message": "in run_until_complete"
              },
              {
                "path": "/usr/lib/python3.10/asyncio/base_events.py",
                "lineno": 584,
                "message": "in _check_running"
              }
            ],
            "longrepr": "../../../.local/lib/python3.10/site-packages/pytest_asyncio/plugin.py:508: in runtest\n    super().runtest()\n../../../.local/lib/python3.10/site-packages/pytest_asyncio/plugin.py:773: in inner\n    _loop.run_until_complete(task)\n/usr/lib/python3.10/asyncio/base_events.py:625: in run_until_complete\n    self._check_running()\n/usr/lib/python3.10/asyncio/base_events.py:584: in _check_running\n    raise RuntimeError('This event loop is already running')\nE   RuntimeError: This event loop is already running"
          },
          "teardown": {
            "duration": 0.00027711299480870366,
            "outcome": "passed"
          }
        },
        {
          "nodeid": "tests/gaea2/test_gaea_failures.py::TestGaea2Failures::test_template_errors",
          "lineno": 459,
          "outcome": "failed",
          "keywords": [
            "test_template_errors",
            "asyncio",
            "pytestmark",
            "TestGaea2Failures",
            "test_gaea_failures.py",
            "gaea2",
            "tests",
            "template-repo",
            ""
          ],
          "setup": {
            "duration": 0.00026491197058930993,
            "outcome": "passed"
          },
          "call": {
            "duration": 0.00018958200234919786,
            "outcome": "failed",
            "crash": {
              "path": "/usr/lib/python3.10/asyncio/base_events.py",
              "lineno": 584,
              "message": "RuntimeError: This event loop is already running"
            },
            "traceback": [
              {
                "path": "../../../.local/lib/python3.10/site-packages/pytest_asyncio/plugin.py",
                "lineno": 508,
                "message": "in runtest"
              },
              {
                "path": "../../../.local/lib/python3.10/site-packages/pytest_asyncio/plugin.py",
                "lineno": 773,
                "message": "in inner"
              },
              {
                "path": "/usr/lib/python3.10/asyncio/base_events.py",
                "lineno": 625,
                "message": "in run_until_complete"
              },
              {
                "path": "/usr/lib/python3.10/asyncio/base_events.py",
                "lineno": 584,
                "message": "in _check_running"
              }
            ],
            "longrepr": "../../../.local/lib/python3.10/site-packages/pytest_asyncio/plugin.py:508: in runtest\n    super().runtest()\n../../../.local/lib/python3.10/site-packages/pytest_asyncio/plugin.py:773: in inner\n    _loop.run_until_complete(task)\n/usr/lib/python3.10/asyncio/base_events.py:625: in run_until_complete\n    self._check_running()\n/usr/lib/python3.10/asyncio/base_events.py:584: in _check_running\n    raise RuntimeError('This event loop is already running')\nE   RuntimeError: This event loop is already running"
          },
          "teardown": {
            "duration": 0.0002091220230795443,
            "outcome": "passed"
          }
        },
        {
          "nodeid": "tests/gaea2/test_gaea_failures.py::TestGaea2Failures::test_connection_type_mismatches",
          "lineno": 486,
          "outcome": "failed",
          "keywords": [
            "test_connection_type_mismatches",
            "asyncio",
            "pytestmark",
            "TestGaea2Failures",
            "test_gaea_failures.py",
            "gaea2",
            "tests",
            "template-repo",
            ""
          ],
          "setup": {
            "duration": 0.00026306300424039364,
            "outcome": "passed"
          },
          "call": {
            "duration": 0.0001492209848947823,
            "outcome": "failed",
            "crash": {
              "path": "/usr/lib/python3.10/asyncio/base_events.py",
              "lineno": 584,
              "message": "RuntimeError: This event loop is already running"
            },
            "traceback": [
              {
                "path": "../../../.local/lib/python3.10/site-packages/pytest_asyncio/plugin.py",
                "lineno": 508,
                "message": "in runtest"
              },
              {
                "path": "../../../.local/lib/python3.10/site-packages/pytest_asyncio/plugin.py",
                "lineno": 773,
                "message": "in inner"
              },
              {
                "path": "/usr/lib/python3.10/asyncio/base_events.py",
                "lineno": 625,
                "message": "in run_until_complete"
              },
              {
                "path": "/usr/lib/python3.10/asyncio/base_events.py",
                "lineno": 584,
                "message": "in _check_running"
              }
            ],
            "longrepr": "../../../.local/lib/python3.10/site-packages/pytest_asyncio/plugin.py:508: in runtest\n    super().runtest()\n../../../.local/lib/python3.10/site-packages/pytest_asyncio/plugin.py:773: in inner\n    _loop.run_until_complete(task)\n/usr/lib/python3.10/asyncio/base_events.py:625: in run_until_complete\n    self._check_running()\n/usr/lib/python3.10/asyncio/base_events.py:584: in _check_running\n    raise RuntimeError('This event loop is already running')\nE   RuntimeError: This event loop is already running"
          },
          "teardown": {
            "duration": 0.00018847198225557804,
            "outcome": "passed"
          }
        },
        {
          "nodeid": "tests/gaea2/test_gaea_failures.py::TestGaea2Failures::test_resource_exhaustion",
          "lineno": 571,
          "outcome": "failed",
          "keywords": [
            "test_resource_exhaustion",
            "asyncio",
            "pytestmark",
            "TestGaea2Failures",
            "test_gaea_failures.py",
            "gaea2",
            "tests",
            "template-repo",
            ""
          ],
          "setup": {
            "duration": 0.0002871630131267011,
            "outcome": "passed"
          },
          "call": {
            "duration": 0.0001479109632782638,
            "outcome": "failed",
            "crash": {
              "path": "/usr/lib/python3.10/asyncio/base_events.py",
              "lineno": 584,
              "message": "RuntimeError: This event loop is already running"
            },
            "traceback": [
              {
                "path": "../../../.local/lib/python3.10/site-packages/pytest_asyncio/plugin.py",
                "lineno": 508,
                "message": "in runtest"
              },
              {
                "path": "../../../.local/lib/python3.10/site-packages/pytest_asyncio/plugin.py",
                "lineno": 773,
                "message": "in inner"
              },
              {
                "path": "/usr/lib/python3.10/asyncio/base_events.py",
                "lineno": 625,
                "message": "in run_until_complete"
              },
              {
                "path": "/usr/lib/python3.10/asyncio/base_events.py",
                "lineno": 584,
                "message": "in _check_running"
              }
            ],
            "longrepr": "../../../.local/lib/python3.10/site-packages/pytest_asyncio/plugin.py:508: in runtest\n    super().runtest()\n../../../.local/lib/python3.10/site-packages/pytest_asyncio/plugin.py:773: in inner\n    _loop.run_until_complete(task)\n/usr/lib/python3.10/asyncio/base_events.py:625: in run_until_complete\n    self._check_running()\n/usr/lib/python3.10/asyncio/base_events.py:584: in _check_running\n    raise RuntimeError('This event loop is already running')\nE   RuntimeError: This event loop is already running"
          },
          "teardown": {
            "duration": 0.00020972196944057941,
            "outcome": "passed"
          }
        },
        {
          "nodeid": "tests/gaea2/test_gaea_failures.py::TestErrorRecovery::test_workflow_auto_repair",
          "lineno": 636,
          "outcome": "failed",
          "keywords": [
            "test_workflow_auto_repair",
            "asyncio",
            "pytestmark",
            "TestErrorRecovery",
            "test_gaea_failures.py",
            "gaea2",
            "tests",
            "template-repo",
            ""
          ],
          "setup": {
            "duration": 0.00024588301312178373,
            "outcome": "passed"
          },
          "call": {
            "duration": 0.00014659203588962555,
            "outcome": "failed",
            "crash": {
              "path": "/usr/lib/python3.10/asyncio/base_events.py",
              "lineno": 584,
              "message": "RuntimeError: This event loop is already running"
            },
            "traceback": [
              {
                "path": "../../../.local/lib/python3.10/site-packages/pytest_asyncio/plugin.py",
                "lineno": 508,
                "message": "in runtest"
              },
              {
                "path": "../../../.local/lib/python3.10/site-packages/pytest_asyncio/plugin.py",
                "lineno": 773,
                "message": "in inner"
              },
              {
                "path": "/usr/lib/python3.10/asyncio/base_events.py",
                "lineno": 625,
                "message": "in run_until_complete"
              },
              {
                "path": "/usr/lib/python3.10/asyncio/base_events.py",
                "lineno": 584,
                "message": "in _check_running"
              }
            ],
            "longrepr": "../../../.local/lib/python3.10/site-packages/pytest_asyncio/plugin.py:508: in runtest\n    super().runtest()\n../../../.local/lib/python3.10/site-packages/pytest_asyncio/plugin.py:773: in inner\n    _loop.run_until_complete(task)\n/usr/lib/python3.10/asyncio/base_events.py:625: in run_until_complete\n    self._check_running()\n/usr/lib/python3.10/asyncio/base_events.py:584: in _check_running\n    raise RuntimeError('This event loop is already running')\nE   RuntimeError: This event loop is already running"
          },
          "teardown": {
            "duration": 0.000290212978143245,
            "outcome": "passed"
          }
        }
      ]
    },
    "regression": {
      "exit_code": 1,
      "total": 8,
      "passed": 0,
      "failed": 7,
      "skipped": 1,
      "duration": 0.22057104110717773,
      "tests": [
        {
          "nodeid": "tests/gaea2/test_gaea_regression.py::TestGaea2Regression::test_template_regression",
          "lineno": 214,
          "outcome": "failed",
          "keywords": [
            "test_template_regression",
            "asyncio",
            "pytestmark",
            "TestGaea2Regression",
            "test_gaea_regression.py",
            "gaea2",
            "tests",
            "template-repo",
            ""
          ],
          "setup": {
            "duration": 0.0009795299847610295,
            "outcome": "passed"
          },
          "call": {
            "duration": 0.00018285197438672185,
            "outcome": "failed",
            "crash": {
              "path": "/usr/lib/python3.10/asyncio/base_events.py",
              "lineno": 584,
              "message": "RuntimeError: This event loop is already running"
            },
            "traceback": [
              {
                "path": "../../../.local/lib/python3.10/site-packages/pytest_asyncio/plugin.py",
                "lineno": 508,
                "message": "in runtest"
              },
              {
                "path": "../../../.local/lib/python3.10/site-packages/pytest_asyncio/plugin.py",
                "lineno": 773,
                "message": "in inner"
              },
              {
                "path": "/usr/lib/python3.10/asyncio/base_events.py",
                "lineno": 625,
                "message": "in run_until_complete"
              },
              {
                "path": "/usr/lib/python3.10/asyncio/base_events.py",
                "lineno": 584,
                "message": "in _check_running"
              }
            ],
            "longrepr": "../../../.local/lib/python3.10/site-packages/pytest_asyncio/plugin.py:508: in runtest\n    super().runtest()\n../../../.local/lib/python3.10/site-packages/pytest_asyncio/plugin.py:773: in inner\n    _loop.run_until_complete(task)\n/usr/lib/python3.10/asyncio/base_events.py:625: in run_until_complete\n    self._check_running()\n/usr/lib/python3.10/asyncio/base_events.py:584: in _check_running\n    raise RuntimeError('This event loop is already running')\nE   RuntimeError: This event loop is already running"
          },
          "teardown": {
            "duration": 0.00027902296278625727,
            "outcome": "passed"
          }
        },
        {
          "nodeid": "tests/gaea2/test_gaea_regression.py::TestGaea2Regression::test_validation_rules_regression",
          "lineno": 259,
          "outcome": "failed",
          "keywords": [
            "test_validation_rules_regression",
            "asyncio",
            "pytestmark",
            "TestGaea2Regression",
            "test_gaea_regression.py",
            "gaea2",
            "tests",
            "template-repo",
            ""
          ],
          "setup": {
            "duration": 0.00040445500053465366,
            "outcome": "passed"
          },
          "call": {
            "duration": 0.00015953200636431575,
            "outcome": "failed",
            "crash": {
              "path": "/usr/lib/python3.10/asyncio/base_events.py",
              "lineno": 584,
              "message": "RuntimeError: This event loop is already running"
            },
            "traceback": [
              {
                "path": "../../../.local/lib/python3.10/site-packages/pytest_asyncio/plugin.py",
                "lineno": 508,
                "message": "in runtest"
              },
              {
                "path": "../../../.local/lib/python3.10/site-packages/pytest_asyncio/plugin.py",
                "lineno": 773,
                "message": "in inner"
              },
              {
                "path": "/usr/lib/python3.10/asyncio/base_events.py",
                "lineno": 625,
                "message": "in run_until_complete"
              },
              {
                "path": "/usr/lib/python3.10/asyncio/base_events.py",
                "lineno": 584,
                "message": "in _check_running"
              }
            ],
            "longrepr": "../../../.local/lib/python3.10/site-packages/pytest_asyncio/plugin.py:508: in runtest\n    super().runtest()\n../../../.local/lib/python3.10/site-packages/pytest_asyncio/plugin.py:773: in inner\n    _loop.run_until_complete(task)\n/usr/lib/python3.10/asyncio/base_events.py:625: in run_until_complete\n    self._check_running()\n/usr/lib/python3.10/asyncio/base_events.py:584: in _check_running\n    raise RuntimeError('This event loop is already running')\nE   RuntimeError: This event loop is already running"
          },
          "teardown": {
            "duration": 0.0002625329652801156,
            "outcome": "passed"
          }
        },
        {
          "nodeid": "tests/gaea2/test_gaea_regression.py::TestGaea2Regression::test_node_behavior_regression",
          "lineno": 327,
          "outcome": "failed",
          "keywords": [
            "test_node_behavior_regression",
            "asyncio",
            "pytestmark",
            "TestGaea2Regression",
            "test_gaea_regression.py",
            "gaea2",
            "tests",
            "template-repo",
            ""
          ],
          "setup": {
            "duration": 0.0003119930042885244,
            "outcome": "passed"
          },
          "call": {
            "duration": 0.00015405198791995645,
            "outcome": "failed",
            "crash": {
              "path": "/usr/lib/python3.10/asyncio/base_events.py",
              "lineno": 584,
              "message": "RuntimeError: This event loop is already running"
            },
            "traceback": [
              {
                "path": "../../../.local/lib/python3.10/site-packages/pytest_asyncio/plugin.py",
                "lineno": 508,
                "message": "in runtest"
              },
              {
                "path": "../../../.local/lib/python3.10/site-packages/pytest_asyncio/plugin.py",
                "lineno": 773,
                "message": "in inner"
              },
              {
                "path": "/usr/lib/python3.10/asyncio/base_events.py",
                "lineno": 625,
                "message": "in run_until_complete"
              },
              {
                "path": "/usr/lib/python3.10/asyncio/base_events.py",
                "lineno": 584,
                "message": "in _check_running"
              }
            ],
            "longrepr": "../../../.local/lib/python3.10/site-packages/pytest_asyncio/plugin.py:508: in runtest\n    super().runtest()\n../../../.local/lib/python3.10/site-packages/pytest_asyncio/plugin.py:773: in inner\n    _loop.run_until_complete(task)\n/usr/lib/python3.10/asyncio/base_events.py:625: in run_until_complete\n    self._check_running()\n/usr/lib/python3.10/asyncio/base_events.py:584: in _check_running\n    raise RuntimeError('This event loop is already running')\nE   RuntimeError: This event loop is already running"
          },
          "teardown": {
            "duration": 0.0002456629881635308,
            "outcome": "passed"
          }
        },
        {
          "nodeid": "tests/gaea2/test_gaea_regression.py::TestGaea2Regression::test_pattern_analysis_regression",
          "lineno": 388,
          "outcome": "failed",
          "keywords": [
            "test_pattern_analysis_regression",
            "asyncio",
            "pytestmark",
            "TestGaea2Regression",
            "test_gaea_regression.py",
            "gaea2",
            "tests",
            "template-repo",
            ""
          ],
          "setup": {
            "duration": 0.0003860939759761095,
            "outcome": "passed"
          },
          "call": {
            "duration": 0.00018020201241597533,
            "outcome": "failed",
            "crash": {
              "path": "/usr/lib/python3.10/asyncio/base_events.py",
              "lineno": 584,
              "message": "RuntimeError: This event loop is already running"
            },
            "traceback": [
              {
                "path": "../../../.local/lib/python3.10/site-packages/pytest_asyncio/plugin.py",
                "lineno": 508,
                "message": "in runtest"
              },
              {
                "path": "../../../.local/lib/python3.10/site-packages/pytest_asyncio/plugin.py",
                "lineno": 773,
                "message": "in inner"
              },
              {
                "path": "/usr/lib/python3.10/asyncio/base_events.py",
                "lineno": 625,
                "message": "in run_until_complete"
              },
              {
                "path": "/usr/lib/python3.10/asyncio/base_events.py",
                "lineno": 584,
                "message": "in _check_running"
              }
            ],
            "longrepr": "../../../.local/lib/python3.10/site-packages/pytest_asyncio/plugin.py:508: in runtest\n    super().runtest()\n../../../.local/lib/python3.10/site-packages/pytest_asyncio/plugin.py:773: in inner\n    _loop.run_until_complete(task)\n/usr/lib/python3.10/asyncio/base_events.py:625: in run_until_complete\n    self._check_running()\n/usr/lib/python3.10/asyncio/base_events.py:584: in _check_running\n    raise RuntimeError('This event loop is already running')\nE   RuntimeError: This event loop is already running"
          },
          "teardown": {
            "duration": 0.0002510020276531577,
            "outcome": "passed"
          }
        },
        {
          "nodeid": "tests/gaea2/test_gaea_regression.py::TestGaea2Regression::test_optimization_regression",
          "lineno": 411,
          "outcome": "failed",
          "keywords": [
            "test_optimization_regression",
            "asyncio",
            "pytestmark",
            "TestGaea2Regression",
            "test_gaea_regression.py",
            "gaea2",
            "tests",
            "template-repo",
            ""
          ],
          "setup": {
            "duration": 0.0003841040306724608,
            "outcome": "passed"
          },
          "call": {
            "duration": 0.00016414100537076592,
            "outcome": "failed",
            "crash": {
              "path": "/usr/lib/python3.10/asyncio/base_events.py",
              "lineno": 584,
              "message": "RuntimeError: This event loop is already running"
            },
            "traceback": [
              {
                "path": "../../../.local/lib/python3.10/site-packages/pytest_asyncio/plugin.py",
                "lineno": 508,
                "message": "in runtest"
              },
              {
                "path": "../../../.local/lib/python3.10/site-packages/pytest_asyncio/plugin.py",
                "lineno": 773,
                "message": "in inner"
              },
              {
                "path": "/usr/lib/python3.10/asyncio/base_events.py",
                "lineno": 625,
                "message": "in run_until_complete"
              },
              {
                "path": "/usr/lib/python3.10/asyncio/base_events.py",
                "lineno": 584,
                "message": "in _check_running"
              }
            ],
            "longrepr": "../../../.local/lib/python3.10/site-packages/pytest_asyncio/plugin.py:508: in runtest\n    super().runtest()\n../../../.local/lib/python3.10/site-packages/pytest_asyncio/plugin.py:773: in inner\n    _loop.run_until_complete(task)\n/usr/lib/python3.10/asyncio/base_events.py:625: in run_until_complete\n    self._check_running()\n/usr/lib/python3.10/asyncio/base_events.py:584: in _check_running\n    raise RuntimeError('This event loop is already running')\nE   RuntimeError: This event loop is already running"
          },
          "teardown": {
            "duration": 0.0002607630449347198,
            "outcome": "passed"
          }
        },
        {
          "nodeid": "tests/gaea2/test_gaea_regression.py::TestGaea2Regression::test_error_handling_regression",
          "lineno": 461,
          "outcome": "skipped",
          "keywords": [
            "test_error_handling_regression",
            "skip",
            "asyncio",
            "pytestmark",
            "TestGaea2Regression",
            "test_gaea_regression.py",
            "gaea2",
            "tests",
            "template-repo",
            ""
          ],
          "setup": {
            "duration": 0.00014251196989789605,
            "outcome": "skipped",
            "longrepr": "('/home/miku/Documents/repos/template-repo/tests/gaea2/test_gaea_regression.py', 462, 'Skipped: Server currently accepts invalid workflows - needs server-side fix')"
          },
          "teardown": {
            "duration": 0.00010184099664911628,
            "outcome": "passed"
          }
        },
        {
          "nodeid": "tests/gaea2/test_gaea_regression.py::TestPerformanceRegression::test_template_performance",
          "lineno": 545,
          "outcome": "failed",
          "keywords": [
            "test_template_performance",
            "asyncio",
            "pytestmark",
            "TestPerformanceRegression",
            "test_gaea_regression.py",
            "gaea2",
            "tests",
            "template-repo",
            ""
          ],
          "setup": {
            "duration": 0.0004540450172498822,
            "outcome": "passed"
          },
          "call": {
            "duration": 0.00017780100461095572,
            "outcome": "failed",
            "crash": {
              "path": "/usr/lib/python3.10/asyncio/base_events.py",
              "lineno": 584,
              "message": "RuntimeError: This event loop is already running"
            },
            "traceback": [
              {
                "path": "../../../.local/lib/python3.10/site-packages/pytest_asyncio/plugin.py",
                "lineno": 508,
                "message": "in runtest"
              },
              {
                "path": "../../../.local/lib/python3.10/site-packages/pytest_asyncio/plugin.py",
                "lineno": 773,
                "message": "in inner"
              },
              {
                "path": "/usr/lib/python3.10/asyncio/base_events.py",
                "lineno": 625,
                "message": "in run_until_complete"
              },
              {
                "path": "/usr/lib/python3.10/asyncio/base_events.py",
                "lineno": 584,
                "message": "in _check_running"
              }
            ],
            "longrepr": "../../../.local/lib/python3.10/site-packages/pytest_asyncio/plugin.py:508: in runtest\n    super().runtest()\n../../../.local/lib/python3.10/site-packages/pytest_asyncio/plugin.py:773: in inner\n    _loop.run_until_complete(task)\n/usr/lib/python3.10/asyncio/base_events.py:625: in run_until_complete\n    self._check_running()\n/usr/lib/python3.10/asyncio/base_events.py:584: in _check_running\n    raise RuntimeError('This event loop is already running')\nE   RuntimeError: This event loop is already running"
          },
          "teardown": {
            "duration": 0.0002849430311471224,
            "outcome": "passed"
          }
        },
        {
          "nodeid": "tests/gaea2/test_gaea_regression.py::TestPerformanceRegression::test_validation_performance",
          "lineno": 571,
          "outcome": "failed",
          "keywords": [
            "test_validation_performance",
            "asyncio",
            "pytestmark",
            "TestPerformanceRegression",
            "test_gaea_regression.py",
            "gaea2",
            "tests",
            "template-repo",
            ""
          ],
          "setup": {
            "duration": 0.00047755398554727435,
            "outcome": "passed"
          },
          "call": {
            "duration": 0.00017852196469902992,
            "outcome": "failed",
            "crash": {
              "path": "/usr/lib/python3.10/asyncio/base_events.py",
              "lineno": 584,
              "message": "RuntimeError: This event loop is already running"
            },
            "traceback": [
              {
                "path": "../../../.local/lib/python3.10/site-packages/pytest_asyncio/plugin.py",
                "lineno": 508,
                "message": "in runtest"
              },
              {
                "path": "../../../.local/lib/python3.10/site-packages/pytest_asyncio/plugin.py",
                "lineno": 773,
                "message": "in inner"
              },
              {
                "path": "/usr/lib/python3.10/asyncio/base_events.py",
                "lineno": 625,
                "message": "in run_until_complete"
              },
              {
                "path": "/usr/lib/python3.10/asyncio/base_events.py",
                "lineno": 584,
                "message": "in _check_running"
              }
            ],
            "longrepr": "../../../.local/lib/python3.10/site-packages/pytest_asyncio/plugin.py:508: in runtest\n    super().runtest()\n../../../.local/lib/python3.10/site-packages/pytest_asyncio/plugin.py:773: in inner\n    _loop.run_until_complete(task)\n/usr/lib/python3.10/asyncio/base_events.py:625: in run_until_complete\n    self._check_running()\n/usr/lib/python3.10/asyncio/base_events.py:584: in _check_running\n    raise RuntimeError('This event loop is already running')\nE   RuntimeError: This event loop is already running"
          },
          "teardown": {
            "duration": 0.0002777519985102117,
            "outcome": "passed"
          }
        }
      ]
    }
  },
  "summary": {},
  "analysis": {
    "total_suites": 5,
    "total_tests": 45,
    "total_passed": 0,
    "total_failed": 44,
    "failed_tests": [
      {
        "suite": "framework_integration",
        "test": "tests/gaea2/test_framework_integration.py::TestSuccessfulOperations::test_create_basic_terrain",
        "error": "../../../.local/lib/python3.10/site-packages/pytest_asyncio/plugin.py:508: in runtest\n    super().runtest()\n../../../.local/lib/python3.10/site-packages/pytest_asyncio/plugin.py:773: in inner\n    _loop.run_until_complete(task)\n/usr/lib/python3.10/asyncio/base_events.py:625: in run_until_complete\n    self._check_running()\n/usr/lib/python3.10/asyncio/base_events.py:584: in _check_running\n    raise RuntimeError('This event loop is already running')\nE   RuntimeError: This event loop is already running"
      },
      {
        "suite": "framework_integration",
        "test": "tests/gaea2/test_framework_integration.py::TestSuccessfulOperations::test_validate_workflow",
        "error": "../../../.local/lib/python3.10/site-packages/pytest_asyncio/plugin.py:508: in runtest\n    super().runtest()\n../../../.local/lib/python3.10/site-packages/pytest_asyncio/plugin.py:773: in inner\n    _loop.run_until_complete(task)\n/usr/lib/python3.10/asyncio/base_events.py:625: in run_until_complete\n    self._check_running()\n/usr/lib/python3.10/asyncio/base_events.py:584: in _check_running\n    raise RuntimeError('This event loop is already running')\nE   RuntimeError: This event loop is already running"
      },
      {
        "suite": "framework_integration",
        "test": "tests/gaea2/test_framework_integration.py::TestSuccessfulOperations::test_analyze_patterns",
        "error": "../../../.local/lib/python3.10/site-packages/pytest_asyncio/plugin.py:508: in runtest\n    super().runtest()\n../../../.local/lib/python3.10/site-packages/pytest_asyncio/plugin.py:773: in inner\n    _loop.run_until_complete(task)\n/usr/lib/python3.10/asyncio/base_events.py:625: in run_until_complete\n    self._check_running()\n/usr/lib/python3.10/asyncio/base_events.py:584: in _check_running\n    raise RuntimeError('This event loop is already running')\nE   RuntimeError: This event loop is already running"
      },
      {
        "suite": "framework_integration",
        "test": "tests/gaea2/test_framework_integration.py::TestSuccessfulOperations::test_node_suggestions",
        "error": "../../../.local/lib/python3.10/site-packages/pytest_asyncio/plugin.py:508: in runtest\n    super().runtest()\n../../../.local/lib/python3.10/site-packages/pytest_asyncio/plugin.py:773: in inner\n    _loop.run_until_complete(task)\n/usr/lib/python3.10/asyncio/base_events.py:625: in run_until_complete\n    self._check_running()\n/usr/lib/python3.10/asyncio/base_events.py:584: in _check_running\n    raise RuntimeError('This event loop is already running')\nE   RuntimeError: This event loop is already running"
      },
      {
        "suite": "framework_integration",
        "test": "tests/gaea2/test_framework_integration.py::TestExpectedFailures::test_invalid_template_name",
        "error": "../../../.local/lib/python3.10/site-packages/pytest_asyncio/plugin.py:508: in runtest\n    super().runtest()\n../../../.local/lib/python3.10/site-packages/pytest_asyncio/plugin.py:773: in inner\n    _loop.run_until_complete(task)\n/usr/lib/python3.10/asyncio/base_events.py:625: in run_until_complete\n    self._check_running()\n/usr/lib/python3.10/asyncio/base_events.py:584: in _check_running\n    raise RuntimeError('This event loop is already running')\nE   RuntimeError: This event loop is already running"
      },
      {
        "suite": "framework_integration",
        "test": "tests/gaea2/test_framework_integration.py::TestExpectedFailures::test_invalid_node_type",
        "error": "../../../.local/lib/python3.10/site-packages/pytest_asyncio/plugin.py:508: in runtest\n    super().runtest()\n../../../.local/lib/python3.10/site-packages/pytest_asyncio/plugin.py:773: in inner\n    _loop.run_until_complete(task)\n/usr/lib/python3.10/asyncio/base_events.py:625: in run_until_complete\n    self._check_running()\n/usr/lib/python3.10/asyncio/base_events.py:584: in _check_running\n    raise RuntimeError('This event loop is already running')\nE   RuntimeError: This event loop is already running"
      },
      {
        "suite": "framework_integration",
        "test": "tests/gaea2/test_framework_integration.py::TestExpectedFailures::test_circular_connections",
        "error": "../../../.local/lib/python3.10/site-packages/pytest_asyncio/plugin.py:508: in runtest\n    super().runtest()\n../../../.local/lib/python3.10/site-packages/pytest_asyncio/plugin.py:773: in inner\n    _loop.run_until_complete(task)\n/usr/lib/python3.10/asyncio/base_events.py:625: in run_until_complete\n    self._check_running()\n/usr/lib/python3.10/asyncio/base_events.py:584: in _check_running\n    raise RuntimeError('This event loop is already running')\nE   RuntimeError: This event loop is already running"
      },
      {
        "suite": "framework_integration",
        "test": "tests/gaea2/test_framework_integration.py::TestEdgeCases::test_empty_workflow",
        "error": "../../../.local/lib/python3.10/site-packages/pytest_asyncio/plugin.py:508: in runtest\n    super().runtest()\n../../../.local/lib/python3.10/site-packages/pytest_asyncio/plugin.py:773: in inner\n    _loop.run_until_complete(task)\n/usr/lib/python3.10/asyncio/base_events.py:625: in run_until_complete\n    self._check_running()\n/usr/lib/python3.10/asyncio/base_events.py:584: in _check_running\n    raise RuntimeError('This event loop is already running')\nE   RuntimeError: This event loop is already running"
      },
      {
        "suite": "framework_integration",
        "test": "tests/gaea2/test_framework_integration.py::TestEdgeCases::test_maximum_complexity",
        "error": "../../../.local/lib/python3.10/site-packages/pytest_asyncio/plugin.py:508: in runtest\n    super().runtest()\n../../../.local/lib/python3.10/site-packages/pytest_asyncio/plugin.py:773: in inner\n    _loop.run_until_complete(task)\n/usr/lib/python3.10/asyncio/base_events.py:625: in run_until_complete\n    self._check_running()\n/usr/lib/python3.10/asyncio/base_events.py:584: in _check_running\n    raise RuntimeError('This event loop is already running')\nE   RuntimeError: This event loop is already running"
      },
      {
        "suite": "framework_integration",
        "test": "tests/gaea2/test_framework_integration.py::TestEdgeCases::test_special_characters_in_names",
        "error": "../../../.local/lib/python3.10/site-packages/pytest_asyncio/plugin.py:508: in runtest\n    super().runtest()\n../../../.local/lib/python3.10/site-packages/pytest_asyncio/plugin.py:773: in inner\n    _loop.run_until_complete(task)\n/usr/lib/python3.10/asyncio/base_events.py:625: in run_until_complete\n    self._check_running()\n/usr/lib/python3.10/asyncio/base_events.py:584: in _check_running\n    raise RuntimeError('This event loop is already running')\nE   RuntimeError: This event loop is already running"
      },
      {
        "suite": "framework_integration",
        "test": "tests/gaea2/test_framework_integration.py::TestErrorHandling::test_malformed_json_handling",
        "error": "../../../.local/lib/python3.10/site-packages/pytest_asyncio/plugin.py:508: in runtest\n    super().runtest()\n../../../.local/lib/python3.10/site-packages/pytest_asyncio/plugin.py:773: in inner\n    _loop.run_until_complete(task)\n/usr/lib/python3.10/asyncio/base_events.py:625: in run_until_complete\n    self._check_running()\n/usr/lib/python3.10/asyncio/base_events.py:584: in _check_running\n    raise RuntimeError('This event loop is already running')\nE   RuntimeError: This event loop is already running"
      },
      {
        "suite": "framework_integration",
        "test": "tests/gaea2/test_framework_integration.py::TestErrorHandling::test_connection_recovery",
        "error": "../../../.local/lib/python3.10/site-packages/pytest_asyncio/plugin.py:508: in runtest\n    super().runtest()\n../../../.local/lib/python3.10/site-packages/pytest_asyncio/plugin.py:773: in inner\n    _loop.run_until_complete(task)\n/usr/lib/python3.10/asyncio/base_events.py:625: in run_until_complete\n    self._check_running()\n/usr/lib/python3.10/asyncio/base_events.py:584: in _check_running\n    raise RuntimeError('This event loop is already running')\nE   RuntimeError: This event loop is already running"
      },
      {
        "suite": "framework_integration",
        "test": "tests/gaea2/test_framework_integration.py::TestErrorHandling::test_timeout_handling",
        "error": "../../../.local/lib/python3.10/site-packages/pytest_asyncio/plugin.py:508: in runtest\n    super().runtest()\n../../../.local/lib/python3.10/site-packages/pytest_asyncio/plugin.py:773: in inner\n    _loop.run_until_complete(task)\n/usr/lib/python3.10/asyncio/base_events.py:625: in run_until_complete\n    self._check_running()\n/usr/lib/python3.10/asyncio/base_events.py:584: in _check_running\n    raise RuntimeError('This event loop is already running')\nE   RuntimeError: This event loop is already running"
      },
      {
        "suite": "framework_integration",
        "test": "tests/gaea2/test_framework_integration.py::TestRegressionSuite::test_template_consistency",
        "error": "../../../.local/lib/python3.10/site-packages/pytest_asyncio/plugin.py:508: in runtest\n    super().runtest()\n../../../.local/lib/python3.10/site-packages/pytest_asyncio/plugin.py:773: in inner\n    _loop.run_until_complete(task)\n/usr/lib/python3.10/asyncio/base_events.py:625: in run_until_complete\n    self._check_running()\n/usr/lib/python3.10/asyncio/base_events.py:584: in _check_running\n    raise RuntimeError('This event loop is already running')\nE   RuntimeError: This event loop is already running"
      },
      {
        "suite": "framework_integration",
        "test": "tests/gaea2/test_framework_integration.py::TestRegressionSuite::test_validation_consistency",
        "error": "../../../.local/lib/python3.10/site-packages/pytest_asyncio/plugin.py:508: in runtest\n    super().runtest()\n../../../.local/lib/python3.10/site-packages/pytest_asyncio/plugin.py:773: in inner\n    _loop.run_until_complete(task)\n/usr/lib/python3.10/asyncio/base_events.py:625: in run_until_complete\n    self._check_running()\n/usr/lib/python3.10/asyncio/base_events.py:584: in _check_running\n    raise RuntimeError('This event loop is already running')\nE   RuntimeError: This event loop is already running"
      },
      {
        "suite": "operations",
        "test": "tests/gaea2/test_gaea_operations.py::TestGaea2Operations::test_common_workflow_pattern",
        "error": "../../../.local/lib/python3.10/site-packages/pytest_asyncio/plugin.py:508: in runtest\n    super().runtest()\n../../../.local/lib/python3.10/site-packages/pytest_asyncio/plugin.py:773: in inner\n    _loop.run_until_complete(task)\n/usr/lib/python3.10/asyncio/base_events.py:625: in run_until_complete\n    self._check_running()\n/usr/lib/python3.10/asyncio/base_events.py:584: in _check_running\n    raise RuntimeError('This event loop is already running')\nE   RuntimeError: This event loop is already running"
      },
      {
        "suite": "operations",
        "test": "tests/gaea2/test_gaea_operations.py::TestGaea2Operations::test_multi_output_nodes",
        "error": "../../../.local/lib/python3.10/site-packages/pytest_asyncio/plugin.py:508: in runtest\n    super().runtest()\n../../../.local/lib/python3.10/site-packages/pytest_asyncio/plugin.py:773: in inner\n    _loop.run_until_complete(task)\n/usr/lib/python3.10/asyncio/base_events.py:625: in run_until_complete\n    self._check_running()\n/usr/lib/python3.10/asyncio/base_events.py:584: in _check_running\n    raise RuntimeError('This event loop is already running')\nE   RuntimeError: This event loop is already running"
      },
      {
        "suite": "operations",
        "test": "tests/gaea2/test_gaea_operations.py::TestGaea2Operations::test_complex_property_nodes",
        "error": "../../../.local/lib/python3.10/site-packages/pytest_asyncio/plugin.py:508: in runtest\n    super().runtest()\n../../../.local/lib/python3.10/site-packages/pytest_asyncio/plugin.py:773: in inner\n    _loop.run_until_complete(task)\n/usr/lib/python3.10/asyncio/base_events.py:625: in run_until_complete\n    self._check_running()\n/usr/lib/python3.10/asyncio/base_events.py:584: in _check_running\n    raise RuntimeError('This event loop is already running')\nE   RuntimeError: This event loop is already running"
      },
      {
        "suite": "operations",
        "test": "tests/gaea2/test_gaea_operations.py::TestGaea2Operations::test_template_variations",
        "error": "../../../.local/lib/python3.10/site-packages/pytest_asyncio/plugin.py:508: in runtest\n    super().runtest()\n../../../.local/lib/python3.10/site-packages/pytest_asyncio/plugin.py:773: in inner\n    _loop.run_until_complete(task)\n/usr/lib/python3.10/asyncio/base_events.py:625: in run_until_complete\n    self._check_running()\n/usr/lib/python3.10/asyncio/base_events.py:584: in _check_running\n    raise RuntimeError('This event loop is already running')\nE   RuntimeError: This event loop is already running"
      },
      {
        "suite": "operations",
        "test": "tests/gaea2/test_gaea_operations.py::TestGaea2Operations::test_combine_node_connections",
        "error": "../../../.local/lib/python3.10/site-packages/pytest_asyncio/plugin.py:508: in runtest\n    super().runtest()\n../../../.local/lib/python3.10/site-packages/pytest_asyncio/plugin.py:773: in inner\n    _loop.run_until_complete(task)\n/usr/lib/python3.10/asyncio/base_events.py:625: in run_until_complete\n    self._check_running()\n/usr/lib/python3.10/asyncio/base_events.py:584: in _check_running\n    raise RuntimeError('This event loop is already running')\nE   RuntimeError: This event loop is already running"
      },
      {
        "suite": "operations",
        "test": "tests/gaea2/test_gaea_operations.py::TestGaea2Operations::test_workflow_optimization",
        "error": "../../../.local/lib/python3.10/site-packages/pytest_asyncio/plugin.py:508: in runtest\n    super().runtest()\n../../../.local/lib/python3.10/site-packages/pytest_asyncio/plugin.py:773: in inner\n    _loop.run_until_complete(task)\n/usr/lib/python3.10/asyncio/base_events.py:625: in run_until_complete\n    self._check_running()\n/usr/lib/python3.10/asyncio/base_events.py:584: in _check_running\n    raise RuntimeError('This event loop is already running')\nE   RuntimeError: This event loop is already running"
      },
      {
        "suite": "operations",
        "test": "tests/gaea2/test_gaea_operations.py::TestGaea2Operations::test_node_suggestions_context",
        "error": "../../../.local/lib/python3.10/site-packages/pytest_asyncio/plugin.py:508: in runtest\n    super().runtest()\n../../../.local/lib/python3.10/site-packages/pytest_asyncio/plugin.py:773: in inner\n    _loop.run_until_complete(task)\n/usr/lib/python3.10/asyncio/base_events.py:625: in run_until_complete\n    self._check_running()\n/usr/lib/python3.10/asyncio/base_events.py:584: in _check_running\n    raise RuntimeError('This event loop is already running')\nE   RuntimeError: This event loop is already running"
      },
      {
        "suite": "operations",
        "test": "tests/gaea2/test_gaea_operations.py::TestGaea2Operations::test_workflow_repair",
        "error": "../../../.local/lib/python3.10/site-packages/pytest_asyncio/plugin.py:508: in runtest\n    super().runtest()\n../../../.local/lib/python3.10/site-packages/pytest_asyncio/plugin.py:773: in inner\n    _loop.run_until_complete(task)\n/usr/lib/python3.10/asyncio/base_events.py:625: in run_until_complete\n    self._check_running()\n/usr/lib/python3.10/asyncio/base_events.py:584: in _check_running\n    raise RuntimeError('This event loop is already running')\nE   RuntimeError: This event loop is already running"
      },
      {
        "suite": "operations",
        "test": "tests/gaea2/test_gaea_operations.py::TestGaea2Operations::test_pattern_analysis",
        "error": "../../../.local/lib/python3.10/site-packages/pytest_asyncio/plugin.py:508: in runtest\n    super().runtest()\n../../../.local/lib/python3.10/site-packages/pytest_asyncio/plugin.py:773: in inner\n    _loop.run_until_complete(task)\n/usr/lib/python3.10/asyncio/base_events.py:625: in run_until_complete\n    self._check_running()\n/usr/lib/python3.10/asyncio/base_events.py:584: in _check_running\n    raise RuntimeError('This event loop is already running')\nE   RuntimeError: This event loop is already running"
      },
      {
        "suite": "operations",
        "test": "tests/gaea2/test_gaea_operations.py::TestGaea2Operations::test_variable_propagation",
        "error": "../../../.local/lib/python3.10/site-packages/pytest_asyncio/plugin.py:508: in runtest\n    super().runtest()\n../../../.local/lib/python3.10/site-packages/pytest_asyncio/plugin.py:773: in inner\n    _loop.run_until_complete(task)\n/usr/lib/python3.10/asyncio/base_events.py:625: in run_until_complete\n    self._check_running()\n/usr/lib/python3.10/asyncio/base_events.py:584: in _check_running\n    raise RuntimeError('This event loop is already running')\nE   RuntimeError: This event loop is already running"
      },
      {
        "suite": "operations",
        "test": "tests/gaea2/test_gaea_operations.py::TestEdgeCasesAndBoundaries::test_maximum_node_limit",
        "error": "../../../.local/lib/python3.10/site-packages/pytest_asyncio/plugin.py:508: in runtest\n    super().runtest()\n../../../.local/lib/python3.10/site-packages/pytest_asyncio/plugin.py:773: in inner\n    _loop.run_until_complete(task)\n/usr/lib/python3.10/asyncio/base_events.py:625: in run_until_complete\n    self._check_running()\n/usr/lib/python3.10/asyncio/base_events.py:584: in _check_running\n    raise RuntimeError('This event loop is already running')\nE   RuntimeError: This event loop is already running"
      },
      {
        "suite": "operations",
        "test": "tests/gaea2/test_gaea_operations.py::TestEdgeCasesAndBoundaries::test_deeply_nested_combines",
        "error": "../../../.local/lib/python3.10/site-packages/pytest_asyncio/plugin.py:508: in runtest\n    super().runtest()\n../../../.local/lib/python3.10/site-packages/pytest_asyncio/plugin.py:773: in inner\n    _loop.run_until_complete(task)\n/usr/lib/python3.10/asyncio/base_events.py:625: in run_until_complete\n    self._check_running()\n/usr/lib/python3.10/asyncio/base_events.py:584: in _check_running\n    raise RuntimeError('This event loop is already running')\nE   RuntimeError: This event loop is already running"
      },
      {
        "suite": "operations",
        "test": "tests/gaea2/test_gaea_operations.py::TestEdgeCasesAndBoundaries::test_special_port_connections",
        "error": "../../../.local/lib/python3.10/site-packages/pytest_asyncio/plugin.py:508: in runtest\n    super().runtest()\n../../../.local/lib/python3.10/site-packages/pytest_asyncio/plugin.py:773: in inner\n    _loop.run_until_complete(task)\n/usr/lib/python3.10/asyncio/base_events.py:625: in run_until_complete\n    self._check_running()\n/usr/lib/python3.10/asyncio/base_events.py:584: in _check_running\n    raise RuntimeError('This event loop is already running')\nE   RuntimeError: This event loop is already running"
      },
      {
        "suite": "failures",
        "test": "tests/gaea2/test_gaea_failures.py::TestGaea2Failures::test_invalid_node_types",
        "error": "../../../.local/lib/python3.10/site-packages/pytest_asyncio/plugin.py:508: in runtest\n    super().runtest()\n../../../.local/lib/python3.10/site-packages/pytest_asyncio/plugin.py:773: in inner\n    _loop.run_until_complete(task)\n/usr/lib/python3.10/asyncio/base_events.py:625: in run_until_complete\n    self._check_running()\n/usr/lib/python3.10/asyncio/base_events.py:584: in _check_running\n    raise RuntimeError('This event loop is already running')\nE   RuntimeError: This event loop is already running"
      },
      {
        "suite": "failures",
        "test": "tests/gaea2/test_gaea_failures.py::TestGaea2Failures::test_invalid_connections",
        "error": "../../../.local/lib/python3.10/site-packages/pytest_asyncio/plugin.py:508: in runtest\n    super().runtest()\n../../../.local/lib/python3.10/site-packages/pytest_asyncio/plugin.py:773: in inner\n    _loop.run_until_complete(task)\n/usr/lib/python3.10/asyncio/base_events.py:625: in run_until_complete\n    self._check_running()\n/usr/lib/python3.10/asyncio/base_events.py:584: in _check_running\n    raise RuntimeError('This event loop is already running')\nE   RuntimeError: This event loop is already running"
      },
      {
        "suite": "failures",
        "test": "tests/gaea2/test_gaea_failures.py::TestGaea2Failures::test_missing_required_nodes",
        "error": "../../../.local/lib/python3.10/site-packages/pytest_asyncio/plugin.py:508: in runtest\n    super().runtest()\n../../../.local/lib/python3.10/site-packages/pytest_asyncio/plugin.py:773: in inner\n    _loop.run_until_complete(task)\n/usr/lib/python3.10/asyncio/base_events.py:625: in run_until_complete\n    self._check_running()\n/usr/lib/python3.10/asyncio/base_events.py:584: in _check_running\n    raise RuntimeError('This event loop is already running')\nE   RuntimeError: This event loop is already running"
      },
      {
        "suite": "failures",
        "test": "tests/gaea2/test_gaea_failures.py::TestGaea2Failures::test_invalid_property_values",
        "error": "../../../.local/lib/python3.10/site-packages/pytest_asyncio/plugin.py:508: in runtest\n    super().runtest()\n../../../.local/lib/python3.10/site-packages/pytest_asyncio/plugin.py:773: in inner\n    _loop.run_until_complete(task)\n/usr/lib/python3.10/asyncio/base_events.py:625: in run_until_complete\n    self._check_running()\n/usr/lib/python3.10/asyncio/base_events.py:584: in _check_running\n    raise RuntimeError('This event loop is already running')\nE   RuntimeError: This event loop is already running"
      },
      {
        "suite": "failures",
        "test": "tests/gaea2/test_gaea_failures.py::TestGaea2Failures::test_malformed_requests",
        "error": "../../../.local/lib/python3.10/site-packages/pytest_asyncio/plugin.py:508: in runtest\n    super().runtest()\n../../../.local/lib/python3.10/site-packages/pytest_asyncio/plugin.py:773: in inner\n    _loop.run_until_complete(task)\n/usr/lib/python3.10/asyncio/base_events.py:625: in run_until_complete\n    self._check_running()\n/usr/lib/python3.10/asyncio/base_events.py:584: in _check_running\n    raise RuntimeError('This event loop is already running')\nE   RuntimeError: This event loop is already running"
      },
      {
        "suite": "failures",
        "test": "tests/gaea2/test_gaea_failures.py::TestGaea2Failures::test_template_errors",
        "error": "../../../.local/lib/python3.10/site-packages/pytest_asyncio/plugin.py:508: in runtest\n    super().runtest()\n../../../.local/lib/python3.10/site-packages/pytest_asyncio/plugin.py:773: in inner\n    _loop.run_until_complete(task)\n/usr/lib/python3.10/asyncio/base_events.py:625: in run_until_complete\n    self._check_running()\n/usr/lib/python3.10/asyncio/base_events.py:584: in _check_running\n    raise RuntimeError('This event loop is already running')\nE   RuntimeError: This event loop is already running"
      },
      {
        "suite": "failures",
        "test": "tests/gaea2/test_gaea_failures.py::TestGaea2Failures::test_connection_type_mismatches",
        "error": "../../../.local/lib/python3.10/site-packages/pytest_asyncio/plugin.py:508: in runtest\n    super().runtest()\n../../../.local/lib/python3.10/site-packages/pytest_asyncio/plugin.py:773: in inner\n    _loop.run_until_complete(task)\n/usr/lib/python3.10/asyncio/base_events.py:625: in run_until_complete\n    self._check_running()\n/usr/lib/python3.10/asyncio/base_events.py:584: in _check_running\n    raise RuntimeError('This event loop is already running')\nE   RuntimeError: This event loop is already running"
      },
      {
        "suite": "failures",
        "test": "tests/gaea2/test_gaea_failures.py::TestGaea2Failures::test_resource_exhaustion",
        "error": "../../../.local/lib/python3.10/site-packages/pytest_asyncio/plugin.py:508: in runtest\n    super().runtest()\n../../../.local/lib/python3.10/site-packages/pytest_asyncio/plugin.py:773: in inner\n    _loop.run_until_complete(task)\n/usr/lib/python3.10/asyncio/base_events.py:625: in run_until_complete\n    self._check_running()\n/usr/lib/python3.10/asyncio/base_events.py:584: in _check_running\n    raise RuntimeError('This event loop is already running')\nE   RuntimeError: This event loop is already running"
      },
      {
        "suite": "failures",
        "test": "tests/gaea2/test_gaea_failures.py::TestErrorRecovery::test_workflow_auto_repair",
        "error": "../../../.local/lib/python3.10/site-packages/pytest_asyncio/plugin.py:508: in runtest\n    super().runtest()\n../../../.local/lib/python3.10/site-packages/pytest_asyncio/plugin.py:773: in inner\n    _loop.run_until_complete(task)\n/usr/lib/python3.10/asyncio/base_events.py:625: in run_until_complete\n    self._check_running()\n/usr/lib/python3.10/asyncio/base_events.py:584: in _check_running\n    raise RuntimeError('This event loop is already running')\nE   RuntimeError: This event loop is already running"
      },
      {
        "suite": "regression",
        "test": "tests/gaea2/test_gaea_regression.py::TestGaea2Regression::test_template_regression",
        "error": "../../../.local/lib/python3.10/site-packages/pytest_asyncio/plugin.py:508: in runtest\n    super().runtest()\n../../../.local/lib/python3.10/site-packages/pytest_asyncio/plugin.py:773: in inner\n    _loop.run_until_complete(task)\n/usr/lib/python3.10/asyncio/base_events.py:625: in run_until_complete\n    self._check_running()\n/usr/lib/python3.10/asyncio/base_events.py:584: in _check_running\n    raise RuntimeError('This event loop is already running')\nE   RuntimeError: This event loop is already running"
      },
      {
        "suite": "regression",
        "test": "tests/gaea2/test_gaea_regression.py::TestGaea2Regression::test_validation_rules_regression",
        "error": "../../../.local/lib/python3.10/site-packages/pytest_asyncio/plugin.py:508: in runtest\n    super().runtest()\n../../../.local/lib/python3.10/site-packages/pytest_asyncio/plugin.py:773: in inner\n    _loop.run_until_complete(task)\n/usr/lib/python3.10/asyncio/base_events.py:625: in run_until_complete\n    self._check_running()\n/usr/lib/python3.10/asyncio/base_events.py:584: in _check_running\n    raise RuntimeError('This event loop is already running')\nE   RuntimeError: This event loop is already running"
      },
      {
        "suite": "regression",
        "test": "tests/gaea2/test_gaea_regression.py::TestGaea2Regression::test_node_behavior_regression",
        "error": "../../../.local/lib/python3.10/site-packages/pytest_asyncio/plugin.py:508: in runtest\n    super().runtest()\n../../../.local/lib/python3.10/site-packages/pytest_asyncio/plugin.py:773: in inner\n    _loop.run_until_complete(task)\n/usr/lib/python3.10/asyncio/base_events.py:625: in run_until_complete\n    self._check_running()\n/usr/lib/python3.10/asyncio/base_events.py:584: in _check_running\n    raise RuntimeError('This event loop is already running')\nE   RuntimeError: This event loop is already running"
      },
      {
        "suite": "regression",
        "test": "tests/gaea2/test_gaea_regression.py::TestGaea2Regression::test_pattern_analysis_regression",
        "error": "../../../.local/lib/python3.10/site-packages/pytest_asyncio/plugin.py:508: in runtest\n    super().runtest()\n../../../.local/lib/python3.10/site-packages/pytest_asyncio/plugin.py:773: in inner\n    _loop.run_until_complete(task)\n/usr/lib/python3.10/asyncio/base_events.py:625: in run_until_complete\n    self._check_running()\n/usr/lib/python3.10/asyncio/base_events.py:584: in _check_running\n    raise RuntimeError('This event loop is already running')\nE   RuntimeError: This event loop is already running"
      },
      {
        "suite": "regression",
        "test": "tests/gaea2/test_gaea_regression.py::TestGaea2Regression::test_optimization_regression",
        "error": "../../../.local/lib/python3.10/site-packages/pytest_asyncio/plugin.py:508: in runtest\n    super().runtest()\n../../../.local/lib/python3.10/site-packages/pytest_asyncio/plugin.py:773: in inner\n    _loop.run_until_complete(task)\n/usr/lib/python3.10/asyncio/base_events.py:625: in run_until_complete\n    self._check_running()\n/usr/lib/python3.10/asyncio/base_events.py:584: in _check_running\n    raise RuntimeError('This event loop is already running')\nE   RuntimeError: This event loop is already running"
      },
      {
        "suite": "regression",
        "test": "tests/gaea2/test_gaea_regression.py::TestPerformanceRegression::test_template_performance",
        "error": "../../../.local/lib/python3.10/site-packages/pytest_asyncio/plugin.py:508: in runtest\n    super().runtest()\n../../../.local/lib/python3.10/site-packages/pytest_asyncio/plugin.py:773: in inner\n    _loop.run_until_complete(task)\n/usr/lib/python3.10/asyncio/base_events.py:625: in run_until_complete\n    self._check_running()\n/usr/lib/python3.10/asyncio/base_events.py:584: in _check_running\n    raise RuntimeError('This event loop is already running')\nE   RuntimeError: This event loop is already running"
      },
      {
        "suite": "regression",
        "test": "tests/gaea2/test_gaea_regression.py::TestPerformanceRegression::test_validation_performance",
        "error": "../../../.local/lib/python3.10/site-packages/pytest_asyncio/plugin.py:508: in runtest\n    super().runtest()\n../../../.local/lib/python3.10/site-packages/pytest_asyncio/plugin.py:773: in inner\n    _loop.run_until_complete(task)\n/usr/lib/python3.10/asyncio/base_events.py:625: in run_until_complete\n    self._check_running()\n/usr/lib/python3.10/asyncio/base_events.py:584: in _check_running\n    raise RuntimeError('This event loop is already running')\nE   RuntimeError: This event loop is already running"
      }
    ],
    "performance_metrics": {
      "framework_integration": 0.4770216941833496,
      "operations": 0.4061875343322754,
      "failures": 0.2755916118621826,
      "regression": 0.22057104110717773
    },
    "common_failures": {},
    "recommendations": []
  },
  "knowledge_update": {
    "timestamp": "2025-07-21T17:51:52.730296",
    "successful_patterns": [],
    "failure_patterns": [
      {
        "test": "tests/gaea2/test_framework_integration.py::TestSuccessfulOperations::test_create_basic_terrain",
        "error_type": "unknown"
      },
      {
        "test": "tests/gaea2/test_framework_integration.py::TestSuccessfulOperations::test_validate_workflow",
        "error_type": "unknown"
      },
      {
        "test": "tests/gaea2/test_framework_integration.py::TestSuccessfulOperations::test_analyze_patterns",
        "error_type": "unknown"
      },
      {
        "test": "tests/gaea2/test_framework_integration.py::TestSuccessfulOperations::test_node_suggestions",
        "error_type": "unknown"
      },
      {
        "test": "tests/gaea2/test_framework_integration.py::TestExpectedFailures::test_invalid_template_name",
        "error_type": "unknown"
      },
      {
        "test": "tests/gaea2/test_framework_integration.py::TestExpectedFailures::test_invalid_node_type",
        "error_type": "unknown"
      },
      {
        "test": "tests/gaea2/test_framework_integration.py::TestExpectedFailures::test_circular_connections",
        "error_type": "unknown"
      },
      {
        "test": "tests/gaea2/test_framework_integration.py::TestEdgeCases::test_empty_workflow",
        "error_type": "unknown"
      },
      {
        "test": "tests/gaea2/test_framework_integration.py::TestEdgeCases::test_maximum_complexity",
        "error_type": "unknown"
      },
      {
        "test": "tests/gaea2/test_framework_integration.py::TestEdgeCases::test_special_characters_in_names",
        "error_type": "unknown"
      },
      {
        "test": "tests/gaea2/test_framework_integration.py::TestErrorHandling::test_malformed_json_handling",
        "error_type": "unknown"
      },
      {
        "test": "tests/gaea2/test_framework_integration.py::TestErrorHandling::test_connection_recovery",
        "error_type": "unknown"
      },
      {
        "test": "tests/gaea2/test_framework_integration.py::TestErrorHandling::test_timeout_handling",
        "error_type": "unknown"
      },
      {
        "test": "tests/gaea2/test_framework_integration.py::TestRegressionSuite::test_template_consistency",
        "error_type": "unknown"
      },
      {
        "test": "tests/gaea2/test_framework_integration.py::TestRegressionSuite::test_validation_consistency",
        "error_type": "unknown"
      },
      {
        "test": "tests/gaea2/test_gaea_operations.py::TestGaea2Operations::test_common_workflow_pattern",
        "error_type": "unknown"
      },
      {
        "test": "tests/gaea2/test_gaea_operations.py::TestGaea2Operations::test_multi_output_nodes",
        "error_type": "unknown"
      },
      {
        "test": "tests/gaea2/test_gaea_operations.py::TestGaea2Operations::test_complex_property_nodes",
        "error_type": "unknown"
      },
      {
        "test": "tests/gaea2/test_gaea_operations.py::TestGaea2Operations::test_template_variations",
        "error_type": "unknown"
      },
      {
        "test": "tests/gaea2/test_gaea_operations.py::TestGaea2Operations::test_combine_node_connections",
        "error_type": "unknown"
      },
      {
        "test": "tests/gaea2/test_gaea_operations.py::TestGaea2Operations::test_workflow_optimization",
        "error_type": "unknown"
      },
      {
        "test": "tests/gaea2/test_gaea_operations.py::TestGaea2Operations::test_node_suggestions_context",
        "error_type": "unknown"
      },
      {
        "test": "tests/gaea2/test_gaea_operations.py::TestGaea2Operations::test_workflow_repair",
        "error_type": "unknown"
      },
      {
        "test": "tests/gaea2/test_gaea_operations.py::TestGaea2Operations::test_pattern_analysis",
        "error_type": "unknown"
      },
      {
        "test": "tests/gaea2/test_gaea_operations.py::TestGaea2Operations::test_variable_propagation",
        "error_type": "unknown"
      },
      {
        "test": "tests/gaea2/test_gaea_operations.py::TestEdgeCasesAndBoundaries::test_maximum_node_limit",
        "error_type": "unknown"
      },
      {
        "test": "tests/gaea2/test_gaea_operations.py::TestEdgeCasesAndBoundaries::test_deeply_nested_combines",
        "error_type": "unknown"
      },
      {
        "test": "tests/gaea2/test_gaea_operations.py::TestEdgeCasesAndBoundaries::test_special_port_connections",
        "error_type": "unknown"
      },
      {
        "test": "tests/gaea2/test_gaea_failures.py::TestGaea2Failures::test_invalid_node_types",
        "error_type": "unknown"
      },
      {
        "test": "tests/gaea2/test_gaea_failures.py::TestGaea2Failures::test_invalid_connections",
        "error_type": "unknown"
      },
      {
        "test": "tests/gaea2/test_gaea_failures.py::TestGaea2Failures::test_missing_required_nodes",
        "error_type": "unknown"
      },
      {
        "test": "tests/gaea2/test_gaea_failures.py::TestGaea2Failures::test_invalid_property_values",
        "error_type": "unknown"
      },
      {
        "test": "tests/gaea2/test_gaea_failures.py::TestGaea2Failures::test_malformed_requests",
        "error_type": "unknown"
      },
      {
        "test": "tests/gaea2/test_gaea_failures.py::TestGaea2Failures::test_template_errors",
        "error_type": "unknown"
      },
      {
        "test": "tests/gaea2/test_gaea_failures.py::TestGaea2Failures::test_connection_type_mismatches",
        "error_type": "unknown"
      },
      {
        "test": "tests/gaea2/test_gaea_failures.py::TestGaea2Failures::test_resource_exhaustion",
        "error_type": "unknown"
      },
      {
        "test": "tests/gaea2/test_gaea_failures.py::TestErrorRecovery::test_workflow_auto_repair",
        "error_type": "unknown"
      },
      {
        "test": "tests/gaea2/test_gaea_regression.py::TestGaea2Regression::test_template_regression",
        "error_type": "unknown"
      },
      {
        "test": "tests/gaea2/test_gaea_regression.py::TestGaea2Regression::test_validation_rules_regression",
        "error_type": "unknown"
      },
      {
        "test": "tests/gaea2/test_gaea_regression.py::TestGaea2Regression::test_node_behavior_regression",
        "error_type": "unknown"
      },
      {
        "test": "tests/gaea2/test_gaea_regression.py::TestGaea2Regression::test_pattern_analysis_regression",
        "error_type": "unknown"
      },
      {
        "test": "tests/gaea2/test_gaea_regression.py::TestGaea2Regression::test_optimization_regression",
        "error_type": "unknown"
      },
      {
        "test": "tests/gaea2/test_gaea_regression.py::TestPerformanceRegression::test_template_performance",
        "error_type": "unknown"
      },
      {
        "test": "tests/gaea2/test_gaea_regression.py::TestPerformanceRegression::test_validation_performance",
        "error_type": "unknown"
      }
    ],
    "edge_cases_discovered": [],
    "performance_benchmarks": {
      "framework_integration": 0.4770216941833496,
      "operations": 0.4061875343322754,
      "failures": 0.2755916118621826,
      "regression": 0.22057104110717773
    }
  }
}
